[Errno 2] File  does not exist: ''
Traceback (most recent call last):
  File "C:\Users\Michael\PycharmProjects\GFWeatherPipelineTask\weather_pipeline.py", line 46, in import_monthly_weather_csv
    frame_out = pd.read_csv(f"{fpath}", na_values=-99).applymap(
  File "C:\Users\Michael\miniconda3\envs\GF Weather Pipeline Task\lib\site-packages\pandas\io\parsers.py", line 676, in parser_f
    return _read(filepath_or_buffer, kwds)
  File "C:\Users\Michael\miniconda3\envs\GF Weather Pipeline Task\lib\site-packages\pandas\io\parsers.py", line 448, in _read
    parser = TextFileReader(fp_or_buf, **kwds)
  File "C:\Users\Michael\miniconda3\envs\GF Weather Pipeline Task\lib\site-packages\pandas\io\parsers.py", line 880, in __init__
    self._make_engine(self.engine)
  File "C:\Users\Michael\miniconda3\envs\GF Weather Pipeline Task\lib\site-packages\pandas\io\parsers.py", line 1114, in _make_engine
    self._engine = CParserWrapper(self.f, **self.options)
  File "C:\Users\Michael\miniconda3\envs\GF Weather Pipeline Task\lib\site-packages\pandas\io\parsers.py", line 1891, in __init__
    self._reader = parsers.TextReader(src, **kwds)
  File "pandas\_libs\parsers.pyx", line 374, in pandas._libs.parsers.TextReader.__cinit__
  File "pandas\_libs\parsers.pyx", line 674, in pandas._libs.parsers.TextReader._setup_parser_source
FileNotFoundError: [Errno 2] File  does not exist: ''
No columns to parse from file
Traceback (most recent call last):
  File "C:\Users\Michael\PycharmProjects\GFWeatherPipelineTask\weather_pipeline.py", line 46, in import_monthly_weather_csv
    frame_out = pd.read_csv(f"{fpath}", na_values=-99).applymap(
  File "C:\Users\Michael\miniconda3\envs\GF Weather Pipeline Task\lib\site-packages\pandas\io\parsers.py", line 676, in parser_f
    return _read(filepath_or_buffer, kwds)
  File "C:\Users\Michael\miniconda3\envs\GF Weather Pipeline Task\lib\site-packages\pandas\io\parsers.py", line 448, in _read
    parser = TextFileReader(fp_or_buf, **kwds)
  File "C:\Users\Michael\miniconda3\envs\GF Weather Pipeline Task\lib\site-packages\pandas\io\parsers.py", line 880, in __init__
    self._make_engine(self.engine)
  File "C:\Users\Michael\miniconda3\envs\GF Weather Pipeline Task\lib\site-packages\pandas\io\parsers.py", line 1114, in _make_engine
    self._engine = CParserWrapper(self.f, **self.options)
  File "C:\Users\Michael\miniconda3\envs\GF Weather Pipeline Task\lib\site-packages\pandas\io\parsers.py", line 1891, in __init__
    self._reader = parsers.TextReader(src, **kwds)
  File "pandas\_libs\parsers.pyx", line 532, in pandas._libs.parsers.TextReader.__cinit__
pandas.errors.EmptyDataError: No columns to parse from file
The file only has a header and no data.
Traceback (most recent call last):
  File "C:\Users\Michael\PycharmProjects\GFWeatherPipelineTask\weather_pipeline.py", line 69, in import_monthly_weather_csv
    raise pd.errors.EmptyDataError("The file only has a header and no data.")
pandas.errors.EmptyDataError: The file only has a header and no data.
'utf-8' codec can't decode byte 0xa3 in position 0: invalid start byte
Traceback (most recent call last):
  File "C:\Users\Michael\PycharmProjects\GFWeatherPipelineTask\weather_pipeline.py", line 46, in import_monthly_weather_csv
    frame_out = pd.read_csv(f"{fpath}", na_values=-99).applymap(
  File "C:\Users\Michael\miniconda3\envs\GF Weather Pipeline Task\lib\site-packages\pandas\io\parsers.py", line 676, in parser_f
    return _read(filepath_or_buffer, kwds)
  File "C:\Users\Michael\miniconda3\envs\GF Weather Pipeline Task\lib\site-packages\pandas\io\parsers.py", line 448, in _read
    parser = TextFileReader(fp_or_buf, **kwds)
  File "C:\Users\Michael\miniconda3\envs\GF Weather Pipeline Task\lib\site-packages\pandas\io\parsers.py", line 880, in __init__
    self._make_engine(self.engine)
  File "C:\Users\Michael\miniconda3\envs\GF Weather Pipeline Task\lib\site-packages\pandas\io\parsers.py", line 1114, in _make_engine
    self._engine = CParserWrapper(self.f, **self.options)
  File "C:\Users\Michael\miniconda3\envs\GF Weather Pipeline Task\lib\site-packages\pandas\io\parsers.py", line 1891, in __init__
    self._reader = parsers.TextReader(src, **kwds)
  File "pandas\_libs\parsers.pyx", line 529, in pandas._libs.parsers.TextReader.__cinit__
  File "pandas\_libs\parsers.pyx", line 749, in pandas._libs.parsers.TextReader._get_header
UnicodeDecodeError: 'utf-8' codec can't decode byte 0xa3 in position 0: invalid start byte
Unexpected column names.
Traceback (most recent call last):
  File "C:\Users\Michael\PycharmProjects\GFWeatherPipelineTask\weather_pipeline.py", line 77, in import_monthly_weather_csv
    raise DataValidationError("Unexpected column names.")
weather_pipeline.DataValidationError: Unexpected column names.
Error tokenizing data. C error: Expected 15 fields in line 3, saw 16
Traceback (most recent call last):
  File "C:\Users\Michael\PycharmProjects\GFWeatherPipelineTask\weather_pipeline.py", line 46, in import_monthly_weather_csv
    frame_out = pd.read_csv(f"{fpath}", na_values=-99).applymap(
  File "C:\Users\Michael\miniconda3\envs\GF Weather Pipeline Task\lib\site-packages\pandas\io\parsers.py", line 676, in parser_f
    return _read(filepath_or_buffer, kwds)
  File "C:\Users\Michael\miniconda3\envs\GF Weather Pipeline Task\lib\site-packages\pandas\io\parsers.py", line 454, in _read
    data = parser.read(nrows)
  File "C:\Users\Michael\miniconda3\envs\GF Weather Pipeline Task\lib\site-packages\pandas\io\parsers.py", line 1133, in read
    ret = self._engine.read(nrows)
  File "C:\Users\Michael\miniconda3\envs\GF Weather Pipeline Task\lib\site-packages\pandas\io\parsers.py", line 2037, in read
    data = self._reader.read(nrows)
  File "pandas\_libs\parsers.pyx", line 860, in pandas._libs.parsers.TextReader.read
  File "pandas\_libs\parsers.pyx", line 875, in pandas._libs.parsers.TextReader._read_low_memory
  File "pandas\_libs\parsers.pyx", line 929, in pandas._libs.parsers.TextReader._read_rows
  File "pandas\_libs\parsers.pyx", line 916, in pandas._libs.parsers.TextReader._tokenize_rows
  File "pandas\_libs\parsers.pyx", line 2071, in pandas._libs.parsers.raise_parser_error
pandas.errors.ParserError: Error tokenizing data. C error: Expected 15 fields in line 3, saw 16

Missing column names or too few row data values.
Traceback (most recent call last):
  File "C:\Users\Michael\PycharmProjects\GFWeatherPipelineTask\weather_pipeline.py", line 72, in import_monthly_weather_csv
    "Missing column names or too few row data values."
weather_pipeline.DataValidationError: Missing column names or too few row data values.
Extra column names or too many row data values.
Traceback (most recent call last):
  File "C:\Users\Michael\PycharmProjects\GFWeatherPipelineTask\weather_pipeline.py", line 75, in import_monthly_weather_csv
    raise DataValidationError("Extra column names or too many row data values.")
weather_pipeline.DataValidationError: Extra column names or too many row data values.
The column ScreenTemperature has a dtype of object which is not a subclass of the required type float64
NoneType: None
The column Longitude has a dtype of object which is not a subclass of the required type float64
NoneType: None
{row: 3, column: "ForecastSiteCode"}: "6" was not in the range [1000, 100000)
NoneType: None
{row: 3, column: "ObservationDate"}: "nan" does not match the date format string "%Y-%m-%dT%H:%M:%S"
NoneType: None
{row: 3, column: "WindDirection"}: "40000" was not in the range [0, 17)
NoneType: None
{row: 3, column: "WindGust"}: "996.0" was not in the range [0, 255)
NoneType: None
{row: 3, column: "ScreenTemperature"}: "KIRKWALL (3017)" was not in the range [-50, 50)
NoneType: None
{row: 3, column: "Pressure"}: "58.95399999999999" was not in the range [870, 1085)
NoneType: None
{row: 3, column: "SignificantWeatherCode"}: "Orkney & Shetland" was not in the range [0, 31)
NoneType: None
{row: 3, column: "Latitude"}: "nan" was not in the range [-90, 90)
NoneType: None
{row: 3, column: "Longitude"}: "nan" was not in the range [-180, 80)
NoneType: None
{row: 6, column: "Longitude"}: "London & South East England" was not in the range [-180, 80)
NoneType: None
{row: 8, column: "ObservationDate"}: "2016-02-07T00:00" does not match the date format string "%Y-%m-%dT%H:%M:%S"
NoneType: None
Data validation failed. Please refer to the log file for detailed information.
Traceback (most recent call last):
  File "C:\Users\Michael\PycharmProjects\GFWeatherPipelineTask\weather_pipeline.py", line 25, in wrapped
    return f(*args, **kwargs)
  File "C:\Users\Michael\PycharmProjects\GFWeatherPipelineTask\weather_pipeline.py", line 204, in validate_weather_data
    "Data validation failed. Please refer to the log file for detailed information."
weather_pipeline.DataValidationError: Data validation failed. Please refer to the log file for detailed information.
[Errno 2] File  does not exist: ''
Traceback (most recent call last):
  File "C:\Users\Michael\PycharmProjects\GFWeatherPipelineTask\weather_pipeline.py", line 46, in import_monthly_weather_csv
    frame_out = pd.read_csv(f"{fpath}", na_values=-99).applymap(
  File "C:\Users\Michael\miniconda3\envs\GF Weather Pipeline Task\lib\site-packages\pandas\io\parsers.py", line 676, in parser_f
    return _read(filepath_or_buffer, kwds)
  File "C:\Users\Michael\miniconda3\envs\GF Weather Pipeline Task\lib\site-packages\pandas\io\parsers.py", line 448, in _read
    parser = TextFileReader(fp_or_buf, **kwds)
  File "C:\Users\Michael\miniconda3\envs\GF Weather Pipeline Task\lib\site-packages\pandas\io\parsers.py", line 880, in __init__
    self._make_engine(self.engine)
  File "C:\Users\Michael\miniconda3\envs\GF Weather Pipeline Task\lib\site-packages\pandas\io\parsers.py", line 1114, in _make_engine
    self._engine = CParserWrapper(self.f, **self.options)
  File "C:\Users\Michael\miniconda3\envs\GF Weather Pipeline Task\lib\site-packages\pandas\io\parsers.py", line 1891, in __init__
    self._reader = parsers.TextReader(src, **kwds)
  File "pandas\_libs\parsers.pyx", line 374, in pandas._libs.parsers.TextReader.__cinit__
  File "pandas\_libs\parsers.pyx", line 674, in pandas._libs.parsers.TextReader._setup_parser_source
FileNotFoundError: [Errno 2] File  does not exist: ''
No columns to parse from file
Traceback (most recent call last):
  File "C:\Users\Michael\PycharmProjects\GFWeatherPipelineTask\weather_pipeline.py", line 46, in import_monthly_weather_csv
    frame_out = pd.read_csv(f"{fpath}", na_values=-99).applymap(
  File "C:\Users\Michael\miniconda3\envs\GF Weather Pipeline Task\lib\site-packages\pandas\io\parsers.py", line 676, in parser_f
    return _read(filepath_or_buffer, kwds)
  File "C:\Users\Michael\miniconda3\envs\GF Weather Pipeline Task\lib\site-packages\pandas\io\parsers.py", line 448, in _read
    parser = TextFileReader(fp_or_buf, **kwds)
  File "C:\Users\Michael\miniconda3\envs\GF Weather Pipeline Task\lib\site-packages\pandas\io\parsers.py", line 880, in __init__
    self._make_engine(self.engine)
  File "C:\Users\Michael\miniconda3\envs\GF Weather Pipeline Task\lib\site-packages\pandas\io\parsers.py", line 1114, in _make_engine
    self._engine = CParserWrapper(self.f, **self.options)
  File "C:\Users\Michael\miniconda3\envs\GF Weather Pipeline Task\lib\site-packages\pandas\io\parsers.py", line 1891, in __init__
    self._reader = parsers.TextReader(src, **kwds)
  File "pandas\_libs\parsers.pyx", line 532, in pandas._libs.parsers.TextReader.__cinit__
pandas.errors.EmptyDataError: No columns to parse from file
The file only has a header and no data.
Traceback (most recent call last):
  File "C:\Users\Michael\PycharmProjects\GFWeatherPipelineTask\weather_pipeline.py", line 69, in import_monthly_weather_csv
    raise pd.errors.EmptyDataError("The file only has a header and no data.")
pandas.errors.EmptyDataError: The file only has a header and no data.
'utf-8' codec can't decode byte 0xa3 in position 0: invalid start byte
Traceback (most recent call last):
  File "C:\Users\Michael\PycharmProjects\GFWeatherPipelineTask\weather_pipeline.py", line 46, in import_monthly_weather_csv
    frame_out = pd.read_csv(f"{fpath}", na_values=-99).applymap(
  File "C:\Users\Michael\miniconda3\envs\GF Weather Pipeline Task\lib\site-packages\pandas\io\parsers.py", line 676, in parser_f
    return _read(filepath_or_buffer, kwds)
  File "C:\Users\Michael\miniconda3\envs\GF Weather Pipeline Task\lib\site-packages\pandas\io\parsers.py", line 448, in _read
    parser = TextFileReader(fp_or_buf, **kwds)
  File "C:\Users\Michael\miniconda3\envs\GF Weather Pipeline Task\lib\site-packages\pandas\io\parsers.py", line 880, in __init__
    self._make_engine(self.engine)
  File "C:\Users\Michael\miniconda3\envs\GF Weather Pipeline Task\lib\site-packages\pandas\io\parsers.py", line 1114, in _make_engine
    self._engine = CParserWrapper(self.f, **self.options)
  File "C:\Users\Michael\miniconda3\envs\GF Weather Pipeline Task\lib\site-packages\pandas\io\parsers.py", line 1891, in __init__
    self._reader = parsers.TextReader(src, **kwds)
  File "pandas\_libs\parsers.pyx", line 529, in pandas._libs.parsers.TextReader.__cinit__
  File "pandas\_libs\parsers.pyx", line 749, in pandas._libs.parsers.TextReader._get_header
UnicodeDecodeError: 'utf-8' codec can't decode byte 0xa3 in position 0: invalid start byte
Unexpected column names.
Traceback (most recent call last):
  File "C:\Users\Michael\PycharmProjects\GFWeatherPipelineTask\weather_pipeline.py", line 77, in import_monthly_weather_csv
    raise DataValidationError("Unexpected column names.")
weather_pipeline.DataValidationError: Unexpected column names.
Error tokenizing data. C error: Expected 15 fields in line 3, saw 16
Traceback (most recent call last):
  File "C:\Users\Michael\PycharmProjects\GFWeatherPipelineTask\weather_pipeline.py", line 46, in import_monthly_weather_csv
    frame_out = pd.read_csv(f"{fpath}", na_values=-99).applymap(
  File "C:\Users\Michael\miniconda3\envs\GF Weather Pipeline Task\lib\site-packages\pandas\io\parsers.py", line 676, in parser_f
    return _read(filepath_or_buffer, kwds)
  File "C:\Users\Michael\miniconda3\envs\GF Weather Pipeline Task\lib\site-packages\pandas\io\parsers.py", line 454, in _read
    data = parser.read(nrows)
  File "C:\Users\Michael\miniconda3\envs\GF Weather Pipeline Task\lib\site-packages\pandas\io\parsers.py", line 1133, in read
    ret = self._engine.read(nrows)
  File "C:\Users\Michael\miniconda3\envs\GF Weather Pipeline Task\lib\site-packages\pandas\io\parsers.py", line 2037, in read
    data = self._reader.read(nrows)
  File "pandas\_libs\parsers.pyx", line 860, in pandas._libs.parsers.TextReader.read
  File "pandas\_libs\parsers.pyx", line 875, in pandas._libs.parsers.TextReader._read_low_memory
  File "pandas\_libs\parsers.pyx", line 929, in pandas._libs.parsers.TextReader._read_rows
  File "pandas\_libs\parsers.pyx", line 916, in pandas._libs.parsers.TextReader._tokenize_rows
  File "pandas\_libs\parsers.pyx", line 2071, in pandas._libs.parsers.raise_parser_error
pandas.errors.ParserError: Error tokenizing data. C error: Expected 15 fields in line 3, saw 16

Missing column names or too few row data values.
Traceback (most recent call last):
  File "C:\Users\Michael\PycharmProjects\GFWeatherPipelineTask\weather_pipeline.py", line 72, in import_monthly_weather_csv
    "Missing column names or too few row data values."
weather_pipeline.DataValidationError: Missing column names or too few row data values.
Extra column names or too many row data values.
Traceback (most recent call last):
  File "C:\Users\Michael\PycharmProjects\GFWeatherPipelineTask\weather_pipeline.py", line 75, in import_monthly_weather_csv
    raise DataValidationError("Extra column names or too many row data values.")
weather_pipeline.DataValidationError: Extra column names or too many row data values.
The column ScreenTemperature has a dtype of object which is not a subclass of the required type float64
NoneType: None
The column Longitude has a dtype of object which is not a subclass of the required type float64
NoneType: None
{row: 3, column: "ForecastSiteCode"}: "6" was not in the range [1000, 100000)
NoneType: None
{row: 3, column: "ObservationDate"}: "nan" does not match the date format string "%Y-%m-%dT%H:%M:%S"
NoneType: None
{row: 3, column: "WindDirection"}: "40000" was not in the range [0, 17)
NoneType: None
{row: 3, column: "WindGust"}: "996.0" was not in the range [0, 255)
NoneType: None
{row: 3, column: "ScreenTemperature"}: "KIRKWALL (3017)" was not in the range [-50, 50)
NoneType: None
{row: 3, column: "Pressure"}: "58.95399999999999" was not in the range [870, 1085)
NoneType: None
{row: 3, column: "SignificantWeatherCode"}: "Orkney & Shetland" was not in the range [0, 31)
NoneType: None
{row: 3, column: "Latitude"}: "nan" was not in the range [-90, 90)
NoneType: None
{row: 3, column: "Longitude"}: "nan" was not in the range [-180, 80)
NoneType: None
{row: 6, column: "Longitude"}: "London & South East England" was not in the range [-180, 80)
NoneType: None
{row: 8, column: "ObservationDate"}: "2016-02-07T00:00" does not match the date format string "%Y-%m-%dT%H:%M:%S"
NoneType: None
Data validation failed. Please refer to the log file for detailed information.
Traceback (most recent call last):
  File "C:\Users\Michael\PycharmProjects\GFWeatherPipelineTask\weather_pipeline.py", line 25, in wrapped
    return f(*args, **kwargs)
  File "C:\Users\Michael\PycharmProjects\GFWeatherPipelineTask\weather_pipeline.py", line 204, in validate_weather_data
    "Data validation failed. Please refer to the log file for detailed information."
weather_pipeline.DataValidationError: Data validation failed. Please refer to the log file for detailed information.
[Errno 2] File  does not exist: ''
Traceback (most recent call last):
  File "C:\Users\Michael\PycharmProjects\GFWeatherPipelineTask\weather_pipeline.py", line 46, in import_monthly_weather_csv
    frame_out = pd.read_csv(f"{fpath}", na_values=-99).applymap(
  File "C:\Users\Michael\miniconda3\envs\GF Weather Pipeline Task\lib\site-packages\pandas\io\parsers.py", line 676, in parser_f
    return _read(filepath_or_buffer, kwds)
  File "C:\Users\Michael\miniconda3\envs\GF Weather Pipeline Task\lib\site-packages\pandas\io\parsers.py", line 448, in _read
    parser = TextFileReader(fp_or_buf, **kwds)
  File "C:\Users\Michael\miniconda3\envs\GF Weather Pipeline Task\lib\site-packages\pandas\io\parsers.py", line 880, in __init__
    self._make_engine(self.engine)
  File "C:\Users\Michael\miniconda3\envs\GF Weather Pipeline Task\lib\site-packages\pandas\io\parsers.py", line 1114, in _make_engine
    self._engine = CParserWrapper(self.f, **self.options)
  File "C:\Users\Michael\miniconda3\envs\GF Weather Pipeline Task\lib\site-packages\pandas\io\parsers.py", line 1891, in __init__
    self._reader = parsers.TextReader(src, **kwds)
  File "pandas\_libs\parsers.pyx", line 374, in pandas._libs.parsers.TextReader.__cinit__
  File "pandas\_libs\parsers.pyx", line 674, in pandas._libs.parsers.TextReader._setup_parser_source
FileNotFoundError: [Errno 2] File  does not exist: ''
No columns to parse from file
Traceback (most recent call last):
  File "C:\Users\Michael\PycharmProjects\GFWeatherPipelineTask\weather_pipeline.py", line 46, in import_monthly_weather_csv
    frame_out = pd.read_csv(f"{fpath}", na_values=-99).applymap(
  File "C:\Users\Michael\miniconda3\envs\GF Weather Pipeline Task\lib\site-packages\pandas\io\parsers.py", line 676, in parser_f
    return _read(filepath_or_buffer, kwds)
  File "C:\Users\Michael\miniconda3\envs\GF Weather Pipeline Task\lib\site-packages\pandas\io\parsers.py", line 448, in _read
    parser = TextFileReader(fp_or_buf, **kwds)
  File "C:\Users\Michael\miniconda3\envs\GF Weather Pipeline Task\lib\site-packages\pandas\io\parsers.py", line 880, in __init__
    self._make_engine(self.engine)
  File "C:\Users\Michael\miniconda3\envs\GF Weather Pipeline Task\lib\site-packages\pandas\io\parsers.py", line 1114, in _make_engine
    self._engine = CParserWrapper(self.f, **self.options)
  File "C:\Users\Michael\miniconda3\envs\GF Weather Pipeline Task\lib\site-packages\pandas\io\parsers.py", line 1891, in __init__
    self._reader = parsers.TextReader(src, **kwds)
  File "pandas\_libs\parsers.pyx", line 532, in pandas._libs.parsers.TextReader.__cinit__
pandas.errors.EmptyDataError: No columns to parse from file
The file only has a header and no data.
Traceback (most recent call last):
  File "C:\Users\Michael\PycharmProjects\GFWeatherPipelineTask\weather_pipeline.py", line 69, in import_monthly_weather_csv
    raise pd.errors.EmptyDataError("The file only has a header and no data.")
pandas.errors.EmptyDataError: The file only has a header and no data.
'utf-8' codec can't decode byte 0xa3 in position 0: invalid start byte
Traceback (most recent call last):
  File "C:\Users\Michael\PycharmProjects\GFWeatherPipelineTask\weather_pipeline.py", line 46, in import_monthly_weather_csv
    frame_out = pd.read_csv(f"{fpath}", na_values=-99).applymap(
  File "C:\Users\Michael\miniconda3\envs\GF Weather Pipeline Task\lib\site-packages\pandas\io\parsers.py", line 676, in parser_f
    return _read(filepath_or_buffer, kwds)
  File "C:\Users\Michael\miniconda3\envs\GF Weather Pipeline Task\lib\site-packages\pandas\io\parsers.py", line 448, in _read
    parser = TextFileReader(fp_or_buf, **kwds)
  File "C:\Users\Michael\miniconda3\envs\GF Weather Pipeline Task\lib\site-packages\pandas\io\parsers.py", line 880, in __init__
    self._make_engine(self.engine)
  File "C:\Users\Michael\miniconda3\envs\GF Weather Pipeline Task\lib\site-packages\pandas\io\parsers.py", line 1114, in _make_engine
    self._engine = CParserWrapper(self.f, **self.options)
  File "C:\Users\Michael\miniconda3\envs\GF Weather Pipeline Task\lib\site-packages\pandas\io\parsers.py", line 1891, in __init__
    self._reader = parsers.TextReader(src, **kwds)
  File "pandas\_libs\parsers.pyx", line 529, in pandas._libs.parsers.TextReader.__cinit__
  File "pandas\_libs\parsers.pyx", line 749, in pandas._libs.parsers.TextReader._get_header
UnicodeDecodeError: 'utf-8' codec can't decode byte 0xa3 in position 0: invalid start byte
Unexpected column names.
Traceback (most recent call last):
  File "C:\Users\Michael\PycharmProjects\GFWeatherPipelineTask\weather_pipeline.py", line 77, in import_monthly_weather_csv
    raise DataValidationError("Unexpected column names.")
weather_pipeline.DataValidationError: Unexpected column names.
Error tokenizing data. C error: Expected 15 fields in line 3, saw 16
Traceback (most recent call last):
  File "C:\Users\Michael\PycharmProjects\GFWeatherPipelineTask\weather_pipeline.py", line 46, in import_monthly_weather_csv
    frame_out = pd.read_csv(f"{fpath}", na_values=-99).applymap(
  File "C:\Users\Michael\miniconda3\envs\GF Weather Pipeline Task\lib\site-packages\pandas\io\parsers.py", line 676, in parser_f
    return _read(filepath_or_buffer, kwds)
  File "C:\Users\Michael\miniconda3\envs\GF Weather Pipeline Task\lib\site-packages\pandas\io\parsers.py", line 454, in _read
    data = parser.read(nrows)
  File "C:\Users\Michael\miniconda3\envs\GF Weather Pipeline Task\lib\site-packages\pandas\io\parsers.py", line 1133, in read
    ret = self._engine.read(nrows)
  File "C:\Users\Michael\miniconda3\envs\GF Weather Pipeline Task\lib\site-packages\pandas\io\parsers.py", line 2037, in read
    data = self._reader.read(nrows)
  File "pandas\_libs\parsers.pyx", line 860, in pandas._libs.parsers.TextReader.read
  File "pandas\_libs\parsers.pyx", line 875, in pandas._libs.parsers.TextReader._read_low_memory
  File "pandas\_libs\parsers.pyx", line 929, in pandas._libs.parsers.TextReader._read_rows
  File "pandas\_libs\parsers.pyx", line 916, in pandas._libs.parsers.TextReader._tokenize_rows
  File "pandas\_libs\parsers.pyx", line 2071, in pandas._libs.parsers.raise_parser_error
pandas.errors.ParserError: Error tokenizing data. C error: Expected 15 fields in line 3, saw 16

Missing column names or too few row data values.
Traceback (most recent call last):
  File "C:\Users\Michael\PycharmProjects\GFWeatherPipelineTask\weather_pipeline.py", line 72, in import_monthly_weather_csv
    "Missing column names or too few row data values."
weather_pipeline.DataValidationError: Missing column names or too few row data values.
Extra column names or too many row data values.
Traceback (most recent call last):
  File "C:\Users\Michael\PycharmProjects\GFWeatherPipelineTask\weather_pipeline.py", line 75, in import_monthly_weather_csv
    raise DataValidationError("Extra column names or too many row data values.")
weather_pipeline.DataValidationError: Extra column names or too many row data values.
The column ScreenTemperature has a dtype of object which is not a subclass of the required type float64
NoneType: None
The column Longitude has a dtype of object which is not a subclass of the required type float64
NoneType: None
{row: 3, column: "ForecastSiteCode"}: "6" was not in the range [1000, 100000)
NoneType: None
{row: 3, column: "ObservationDate"}: "nan" does not match the date format string "%Y-%m-%dT%H:%M:%S"
NoneType: None
{row: 3, column: "WindDirection"}: "40000" was not in the range [0, 17)
NoneType: None
{row: 3, column: "WindGust"}: "996.0" was not in the range [0, 255)
NoneType: None
{row: 3, column: "ScreenTemperature"}: "KIRKWALL (3017)" was not in the range [-50, 50)
NoneType: None
{row: 3, column: "Pressure"}: "58.95399999999999" was not in the range [870, 1085)
NoneType: None
{row: 3, column: "SignificantWeatherCode"}: "Orkney & Shetland" was not in the range [0, 31)
NoneType: None
{row: 3, column: "Latitude"}: "nan" was not in the range [-90, 90)
NoneType: None
{row: 3, column: "Longitude"}: "nan" was not in the range [-180, 80)
NoneType: None
{row: 6, column: "Longitude"}: "London & South East England" was not in the range [-180, 80)
NoneType: None
{row: 8, column: "ObservationDate"}: "2016-02-07T00:00" does not match the date format string "%Y-%m-%dT%H:%M:%S"
NoneType: None
Data validation failed. Please refer to the log file for detailed information.
Traceback (most recent call last):
  File "C:\Users\Michael\PycharmProjects\GFWeatherPipelineTask\weather_pipeline.py", line 25, in wrapped
    return f(*args, **kwargs)
  File "C:\Users\Michael\PycharmProjects\GFWeatherPipelineTask\weather_pipeline.py", line 204, in validate_weather_data
    "Data validation failed. Please refer to the log file for detailed information."
weather_pipeline.DataValidationError: Data validation failed. Please refer to the log file for detailed information.
TransportError(500, '{\r\n  "errorMessage" : "VALIDATION ERROR: From line 8, column 17 to line 8, column 19: Object \'C:/Users/Michael/PycharmProjects/GFWeatherPipelineTask/Data/wether.parquet\' not found within \'dfs\'\\n\\n\\r\\n[Error Id: 0a0fb6d0-024f-402f-b9d6-ac68f0d5c7a6 ]"\r\n}')
Traceback (most recent call last):
  File "C:\Users\Michael\PycharmProjects\GFWeatherPipelineTask\weather_pipeline.py", line 25, in wrapped
    return f(*args, **kwargs)
  File "C:\Users\Michael\PycharmProjects\GFWeatherPipelineTask\weather_pipeline.py", line 354, in query_parquet
    return drill.query(sql, timeout=10)
  File "C:\Users\Michael\miniconda3\envs\GF Weather Pipeline Task\lib\site-packages\pydrill\client\__init__.py", line 62, in query
    'request_timeout': timeout
  File "C:\Users\Michael\miniconda3\envs\GF Weather Pipeline Task\lib\site-packages\pydrill\client\__init__.py", line 24, in perform_request
    return self.transport.perform_request(method, url, params, body)
  File "C:\Users\Michael\miniconda3\envs\GF Weather Pipeline Task\lib\site-packages\pydrill\transport.py", line 79, in perform_request
    timeout=timeout)
  File "C:\Users\Michael\miniconda3\envs\GF Weather Pipeline Task\lib\site-packages\pydrill\connection\requests_conn.py", line 105, in perform_request
    self._raise_error(response.status_code, raw_data)
  File "C:\Users\Michael\miniconda3\envs\GF Weather Pipeline Task\lib\site-packages\pydrill\connection\base.py", line 113, in _raise_error
    raise HTTP_EXCEPTIONS.get(status_code, TransportError)(status_code, error_message, additional_info)
pydrill.exceptions.TransportError: TransportError(500, '{\r\n  "errorMessage" : "VALIDATION ERROR: From line 8, column 17 to line 8, column 19: Object \'C:/Users/Michael/PycharmProjects/GFWeatherPipelineTask/Data/wether.parquet\' not found within \'dfs\'\\n\\n\\r\\n[Error Id: 0a0fb6d0-024f-402f-b9d6-ac68f0d5c7a6 ]"\r\n}')
TransportError(500, '{\r\n  "errorMessage" : "VALIDATION ERROR: From line 8, column 17 to line 8, column 19: Object \'C:/Users/Michael/PycharmProjects/GFWeatherPipelineTask/Data/wether.parquet\' not found within \'dfs\'\\n\\n\\r\\n[Error Id: 0a0fb6d0-024f-402f-b9d6-ac68f0d5c7a6 ]"\r\n}')
Traceback (most recent call last):
  File "C:\Users\Michael\PycharmProjects\GFWeatherPipelineTask\weather_pipeline.py", line 25, in wrapped
    return f(*args, **kwargs)
  File "C:\Users\Michael\PycharmProjects\GFWeatherPipelineTask\weather_pipeline.py", line 336, in max_daily_average_temperature
    query_out = query_parquet(sql)
  File "C:\Users\Michael\PycharmProjects\GFWeatherPipelineTask\weather_pipeline.py", line 25, in wrapped
    return f(*args, **kwargs)
  File "C:\Users\Michael\PycharmProjects\GFWeatherPipelineTask\weather_pipeline.py", line 354, in query_parquet
    return drill.query(sql, timeout=10)
  File "C:\Users\Michael\miniconda3\envs\GF Weather Pipeline Task\lib\site-packages\pydrill\client\__init__.py", line 62, in query
    'request_timeout': timeout
  File "C:\Users\Michael\miniconda3\envs\GF Weather Pipeline Task\lib\site-packages\pydrill\client\__init__.py", line 24, in perform_request
    return self.transport.perform_request(method, url, params, body)
  File "C:\Users\Michael\miniconda3\envs\GF Weather Pipeline Task\lib\site-packages\pydrill\transport.py", line 79, in perform_request
    timeout=timeout)
  File "C:\Users\Michael\miniconda3\envs\GF Weather Pipeline Task\lib\site-packages\pydrill\connection\requests_conn.py", line 105, in perform_request
    self._raise_error(response.status_code, raw_data)
  File "C:\Users\Michael\miniconda3\envs\GF Weather Pipeline Task\lib\site-packages\pydrill\connection\base.py", line 113, in _raise_error
    raise HTTP_EXCEPTIONS.get(status_code, TransportError)(status_code, error_message, additional_info)
pydrill.exceptions.TransportError: TransportError(500, '{\r\n  "errorMessage" : "VALIDATION ERROR: From line 8, column 17 to line 8, column 19: Object \'C:/Users/Michael/PycharmProjects/GFWeatherPipelineTask/Data/wether.parquet\' not found within \'dfs\'\\n\\n\\r\\n[Error Id: 0a0fb6d0-024f-402f-b9d6-ac68f0d5c7a6 ]"\r\n}')
[Errno 2] File  does not exist: ''
Traceback (most recent call last):
  File "C:\Users\Michael\PycharmProjects\GFWeatherPipelineTask\weather_pipeline.py", line 46, in import_monthly_weather_csv
    frame_out = pd.read_csv(f"{fpath}", na_values=-99).applymap(
  File "C:\Users\Michael\miniconda3\envs\GF Weather Pipeline Task\lib\site-packages\pandas\io\parsers.py", line 676, in parser_f
    return _read(filepath_or_buffer, kwds)
  File "C:\Users\Michael\miniconda3\envs\GF Weather Pipeline Task\lib\site-packages\pandas\io\parsers.py", line 448, in _read
    parser = TextFileReader(fp_or_buf, **kwds)
  File "C:\Users\Michael\miniconda3\envs\GF Weather Pipeline Task\lib\site-packages\pandas\io\parsers.py", line 880, in __init__
    self._make_engine(self.engine)
  File "C:\Users\Michael\miniconda3\envs\GF Weather Pipeline Task\lib\site-packages\pandas\io\parsers.py", line 1114, in _make_engine
    self._engine = CParserWrapper(self.f, **self.options)
  File "C:\Users\Michael\miniconda3\envs\GF Weather Pipeline Task\lib\site-packages\pandas\io\parsers.py", line 1891, in __init__
    self._reader = parsers.TextReader(src, **kwds)
  File "pandas\_libs\parsers.pyx", line 374, in pandas._libs.parsers.TextReader.__cinit__
  File "pandas\_libs\parsers.pyx", line 674, in pandas._libs.parsers.TextReader._setup_parser_source
FileNotFoundError: [Errno 2] File  does not exist: ''
No columns to parse from file
Traceback (most recent call last):
  File "C:\Users\Michael\PycharmProjects\GFWeatherPipelineTask\weather_pipeline.py", line 46, in import_monthly_weather_csv
    frame_out = pd.read_csv(f"{fpath}", na_values=-99).applymap(
  File "C:\Users\Michael\miniconda3\envs\GF Weather Pipeline Task\lib\site-packages\pandas\io\parsers.py", line 676, in parser_f
    return _read(filepath_or_buffer, kwds)
  File "C:\Users\Michael\miniconda3\envs\GF Weather Pipeline Task\lib\site-packages\pandas\io\parsers.py", line 448, in _read
    parser = TextFileReader(fp_or_buf, **kwds)
  File "C:\Users\Michael\miniconda3\envs\GF Weather Pipeline Task\lib\site-packages\pandas\io\parsers.py", line 880, in __init__
    self._make_engine(self.engine)
  File "C:\Users\Michael\miniconda3\envs\GF Weather Pipeline Task\lib\site-packages\pandas\io\parsers.py", line 1114, in _make_engine
    self._engine = CParserWrapper(self.f, **self.options)
  File "C:\Users\Michael\miniconda3\envs\GF Weather Pipeline Task\lib\site-packages\pandas\io\parsers.py", line 1891, in __init__
    self._reader = parsers.TextReader(src, **kwds)
  File "pandas\_libs\parsers.pyx", line 532, in pandas._libs.parsers.TextReader.__cinit__
pandas.errors.EmptyDataError: No columns to parse from file
The file only has a header and no data.
Traceback (most recent call last):
  File "C:\Users\Michael\PycharmProjects\GFWeatherPipelineTask\weather_pipeline.py", line 69, in import_monthly_weather_csv
    raise pd.errors.EmptyDataError("The file only has a header and no data.")
pandas.errors.EmptyDataError: The file only has a header and no data.
'utf-8' codec can't decode byte 0xa3 in position 0: invalid start byte
Traceback (most recent call last):
  File "C:\Users\Michael\PycharmProjects\GFWeatherPipelineTask\weather_pipeline.py", line 46, in import_monthly_weather_csv
    frame_out = pd.read_csv(f"{fpath}", na_values=-99).applymap(
  File "C:\Users\Michael\miniconda3\envs\GF Weather Pipeline Task\lib\site-packages\pandas\io\parsers.py", line 676, in parser_f
    return _read(filepath_or_buffer, kwds)
  File "C:\Users\Michael\miniconda3\envs\GF Weather Pipeline Task\lib\site-packages\pandas\io\parsers.py", line 448, in _read
    parser = TextFileReader(fp_or_buf, **kwds)
  File "C:\Users\Michael\miniconda3\envs\GF Weather Pipeline Task\lib\site-packages\pandas\io\parsers.py", line 880, in __init__
    self._make_engine(self.engine)
  File "C:\Users\Michael\miniconda3\envs\GF Weather Pipeline Task\lib\site-packages\pandas\io\parsers.py", line 1114, in _make_engine
    self._engine = CParserWrapper(self.f, **self.options)
  File "C:\Users\Michael\miniconda3\envs\GF Weather Pipeline Task\lib\site-packages\pandas\io\parsers.py", line 1891, in __init__
    self._reader = parsers.TextReader(src, **kwds)
  File "pandas\_libs\parsers.pyx", line 529, in pandas._libs.parsers.TextReader.__cinit__
  File "pandas\_libs\parsers.pyx", line 749, in pandas._libs.parsers.TextReader._get_header
UnicodeDecodeError: 'utf-8' codec can't decode byte 0xa3 in position 0: invalid start byte
Unexpected column names.
Traceback (most recent call last):
  File "C:\Users\Michael\PycharmProjects\GFWeatherPipelineTask\weather_pipeline.py", line 77, in import_monthly_weather_csv
    raise DataValidationError("Unexpected column names.")
weather_pipeline.DataValidationError: Unexpected column names.
Error tokenizing data. C error: Expected 15 fields in line 3, saw 16
Traceback (most recent call last):
  File "C:\Users\Michael\PycharmProjects\GFWeatherPipelineTask\weather_pipeline.py", line 46, in import_monthly_weather_csv
    frame_out = pd.read_csv(f"{fpath}", na_values=-99).applymap(
  File "C:\Users\Michael\miniconda3\envs\GF Weather Pipeline Task\lib\site-packages\pandas\io\parsers.py", line 676, in parser_f
    return _read(filepath_or_buffer, kwds)
  File "C:\Users\Michael\miniconda3\envs\GF Weather Pipeline Task\lib\site-packages\pandas\io\parsers.py", line 454, in _read
    data = parser.read(nrows)
  File "C:\Users\Michael\miniconda3\envs\GF Weather Pipeline Task\lib\site-packages\pandas\io\parsers.py", line 1133, in read
    ret = self._engine.read(nrows)
  File "C:\Users\Michael\miniconda3\envs\GF Weather Pipeline Task\lib\site-packages\pandas\io\parsers.py", line 2037, in read
    data = self._reader.read(nrows)
  File "pandas\_libs\parsers.pyx", line 860, in pandas._libs.parsers.TextReader.read
  File "pandas\_libs\parsers.pyx", line 875, in pandas._libs.parsers.TextReader._read_low_memory
  File "pandas\_libs\parsers.pyx", line 929, in pandas._libs.parsers.TextReader._read_rows
  File "pandas\_libs\parsers.pyx", line 916, in pandas._libs.parsers.TextReader._tokenize_rows
  File "pandas\_libs\parsers.pyx", line 2071, in pandas._libs.parsers.raise_parser_error
pandas.errors.ParserError: Error tokenizing data. C error: Expected 15 fields in line 3, saw 16

Missing column names or too few row data values.
Traceback (most recent call last):
  File "C:\Users\Michael\PycharmProjects\GFWeatherPipelineTask\weather_pipeline.py", line 72, in import_monthly_weather_csv
    "Missing column names or too few row data values."
weather_pipeline.DataValidationError: Missing column names or too few row data values.
Extra column names or too many row data values.
Traceback (most recent call last):
  File "C:\Users\Michael\PycharmProjects\GFWeatherPipelineTask\weather_pipeline.py", line 75, in import_monthly_weather_csv
    raise DataValidationError("Extra column names or too many row data values.")
weather_pipeline.DataValidationError: Extra column names or too many row data values.
The column ScreenTemperature has a dtype of object which is not a subclass of the required type float64
NoneType: None
The column Longitude has a dtype of object which is not a subclass of the required type float64
NoneType: None
{row: 3, column: "ForecastSiteCode"}: "6" was not in the range [1000, 100000)
NoneType: None
{row: 3, column: "ObservationDate"}: "nan" does not match the date format string "%Y-%m-%dT%H:%M:%S"
NoneType: None
{row: 3, column: "WindDirection"}: "40000" was not in the range [0, 17)
NoneType: None
{row: 3, column: "WindGust"}: "996.0" was not in the range [0, 255)
NoneType: None
{row: 3, column: "ScreenTemperature"}: "KIRKWALL (3017)" was not in the range [-50, 50)
NoneType: None
{row: 3, column: "Pressure"}: "58.95399999999999" was not in the range [870, 1085)
NoneType: None
{row: 3, column: "SignificantWeatherCode"}: "Orkney & Shetland" was not in the range [0, 31)
NoneType: None
{row: 3, column: "Latitude"}: "nan" was not in the range [-90, 90)
NoneType: None
{row: 3, column: "Longitude"}: "nan" was not in the range [-180, 80)
NoneType: None
{row: 6, column: "Longitude"}: "London & South East England" was not in the range [-180, 80)
NoneType: None
{row: 8, column: "ObservationDate"}: "2016-02-07T00:00" does not match the date format string "%Y-%m-%dT%H:%M:%S"
NoneType: None
Data validation failed. Please refer to the log file for detailed information.
Traceback (most recent call last):
  File "C:\Users\Michael\PycharmProjects\GFWeatherPipelineTask\weather_pipeline.py", line 25, in wrapped
    return f(*args, **kwargs)
  File "C:\Users\Michael\PycharmProjects\GFWeatherPipelineTask\weather_pipeline.py", line 204, in validate_weather_data
    "Data validation failed. Please refer to the log file for detailed information."
weather_pipeline.DataValidationError: Data validation failed. Please refer to the log file for detailed information.
TransportError(500, '{\r\n  "errorMessage" : "VALIDATION ERROR: From line 8, column 17 to line 8, column 19: Object \'C:/Users/Michael/PycharmProjects/GFWeatherPipelineTask/Data/wether.parquet\' not found within \'dfs\'\\n\\n\\r\\n[Error Id: 3a4ca2a2-481e-4df2-9f26-dd71fbe68548 ]"\r\n}')
Traceback (most recent call last):
  File "C:\Users\Michael\PycharmProjects\GFWeatherPipelineTask\weather_pipeline.py", line 25, in wrapped
    return f(*args, **kwargs)
  File "C:\Users\Michael\PycharmProjects\GFWeatherPipelineTask\weather_pipeline.py", line 354, in query_parquet
    return drill.query(sql, timeout=10)
  File "C:\Users\Michael\miniconda3\envs\GF Weather Pipeline Task\lib\site-packages\pydrill\client\__init__.py", line 62, in query
    'request_timeout': timeout
  File "C:\Users\Michael\miniconda3\envs\GF Weather Pipeline Task\lib\site-packages\pydrill\client\__init__.py", line 24, in perform_request
    return self.transport.perform_request(method, url, params, body)
  File "C:\Users\Michael\miniconda3\envs\GF Weather Pipeline Task\lib\site-packages\pydrill\transport.py", line 79, in perform_request
    timeout=timeout)
  File "C:\Users\Michael\miniconda3\envs\GF Weather Pipeline Task\lib\site-packages\pydrill\connection\requests_conn.py", line 105, in perform_request
    self._raise_error(response.status_code, raw_data)
  File "C:\Users\Michael\miniconda3\envs\GF Weather Pipeline Task\lib\site-packages\pydrill\connection\base.py", line 113, in _raise_error
    raise HTTP_EXCEPTIONS.get(status_code, TransportError)(status_code, error_message, additional_info)
pydrill.exceptions.TransportError: TransportError(500, '{\r\n  "errorMessage" : "VALIDATION ERROR: From line 8, column 17 to line 8, column 19: Object \'C:/Users/Michael/PycharmProjects/GFWeatherPipelineTask/Data/wether.parquet\' not found within \'dfs\'\\n\\n\\r\\n[Error Id: 3a4ca2a2-481e-4df2-9f26-dd71fbe68548 ]"\r\n}')
TransportError(500, '{\r\n  "errorMessage" : "VALIDATION ERROR: From line 8, column 17 to line 8, column 19: Object \'C:/Users/Michael/PycharmProjects/GFWeatherPipelineTask/Data/wether.parquet\' not found within \'dfs\'\\n\\n\\r\\n[Error Id: 3a4ca2a2-481e-4df2-9f26-dd71fbe68548 ]"\r\n}')
Traceback (most recent call last):
  File "C:\Users\Michael\PycharmProjects\GFWeatherPipelineTask\weather_pipeline.py", line 25, in wrapped
    return f(*args, **kwargs)
  File "C:\Users\Michael\PycharmProjects\GFWeatherPipelineTask\weather_pipeline.py", line 336, in max_daily_average_temperature
    query_out = query_parquet(sql)
  File "C:\Users\Michael\PycharmProjects\GFWeatherPipelineTask\weather_pipeline.py", line 25, in wrapped
    return f(*args, **kwargs)
  File "C:\Users\Michael\PycharmProjects\GFWeatherPipelineTask\weather_pipeline.py", line 354, in query_parquet
    return drill.query(sql, timeout=10)
  File "C:\Users\Michael\miniconda3\envs\GF Weather Pipeline Task\lib\site-packages\pydrill\client\__init__.py", line 62, in query
    'request_timeout': timeout
  File "C:\Users\Michael\miniconda3\envs\GF Weather Pipeline Task\lib\site-packages\pydrill\client\__init__.py", line 24, in perform_request
    return self.transport.perform_request(method, url, params, body)
  File "C:\Users\Michael\miniconda3\envs\GF Weather Pipeline Task\lib\site-packages\pydrill\transport.py", line 79, in perform_request
    timeout=timeout)
  File "C:\Users\Michael\miniconda3\envs\GF Weather Pipeline Task\lib\site-packages\pydrill\connection\requests_conn.py", line 105, in perform_request
    self._raise_error(response.status_code, raw_data)
  File "C:\Users\Michael\miniconda3\envs\GF Weather Pipeline Task\lib\site-packages\pydrill\connection\base.py", line 113, in _raise_error
    raise HTTP_EXCEPTIONS.get(status_code, TransportError)(status_code, error_message, additional_info)
pydrill.exceptions.TransportError: TransportError(500, '{\r\n  "errorMessage" : "VALIDATION ERROR: From line 8, column 17 to line 8, column 19: Object \'C:/Users/Michael/PycharmProjects/GFWeatherPipelineTask/Data/wether.parquet\' not found within \'dfs\'\\n\\n\\r\\n[Error Id: 3a4ca2a2-481e-4df2-9f26-dd71fbe68548 ]"\r\n}')
[Errno 2] File  does not exist: ''
Traceback (most recent call last):
  File "C:\Users\Michael\PycharmProjects\GFWeatherPipelineTask\weather_pipeline.py", line 46, in import_monthly_weather_csv
    frame_out = pd.read_csv(f"{fpath}", na_values=-99).applymap(
  File "C:\Users\Michael\miniconda3\envs\GF Weather Pipeline Task\lib\site-packages\pandas\io\parsers.py", line 676, in parser_f
    return _read(filepath_or_buffer, kwds)
  File "C:\Users\Michael\miniconda3\envs\GF Weather Pipeline Task\lib\site-packages\pandas\io\parsers.py", line 448, in _read
    parser = TextFileReader(fp_or_buf, **kwds)
  File "C:\Users\Michael\miniconda3\envs\GF Weather Pipeline Task\lib\site-packages\pandas\io\parsers.py", line 880, in __init__
    self._make_engine(self.engine)
  File "C:\Users\Michael\miniconda3\envs\GF Weather Pipeline Task\lib\site-packages\pandas\io\parsers.py", line 1114, in _make_engine
    self._engine = CParserWrapper(self.f, **self.options)
  File "C:\Users\Michael\miniconda3\envs\GF Weather Pipeline Task\lib\site-packages\pandas\io\parsers.py", line 1891, in __init__
    self._reader = parsers.TextReader(src, **kwds)
  File "pandas\_libs\parsers.pyx", line 374, in pandas._libs.parsers.TextReader.__cinit__
  File "pandas\_libs\parsers.pyx", line 674, in pandas._libs.parsers.TextReader._setup_parser_source
FileNotFoundError: [Errno 2] File  does not exist: ''
No columns to parse from file
Traceback (most recent call last):
  File "C:\Users\Michael\PycharmProjects\GFWeatherPipelineTask\weather_pipeline.py", line 46, in import_monthly_weather_csv
    frame_out = pd.read_csv(f"{fpath}", na_values=-99).applymap(
  File "C:\Users\Michael\miniconda3\envs\GF Weather Pipeline Task\lib\site-packages\pandas\io\parsers.py", line 676, in parser_f
    return _read(filepath_or_buffer, kwds)
  File "C:\Users\Michael\miniconda3\envs\GF Weather Pipeline Task\lib\site-packages\pandas\io\parsers.py", line 448, in _read
    parser = TextFileReader(fp_or_buf, **kwds)
  File "C:\Users\Michael\miniconda3\envs\GF Weather Pipeline Task\lib\site-packages\pandas\io\parsers.py", line 880, in __init__
    self._make_engine(self.engine)
  File "C:\Users\Michael\miniconda3\envs\GF Weather Pipeline Task\lib\site-packages\pandas\io\parsers.py", line 1114, in _make_engine
    self._engine = CParserWrapper(self.f, **self.options)
  File "C:\Users\Michael\miniconda3\envs\GF Weather Pipeline Task\lib\site-packages\pandas\io\parsers.py", line 1891, in __init__
    self._reader = parsers.TextReader(src, **kwds)
  File "pandas\_libs\parsers.pyx", line 532, in pandas._libs.parsers.TextReader.__cinit__
pandas.errors.EmptyDataError: No columns to parse from file
The file only has a header and no data.
Traceback (most recent call last):
  File "C:\Users\Michael\PycharmProjects\GFWeatherPipelineTask\weather_pipeline.py", line 69, in import_monthly_weather_csv
    raise pd.errors.EmptyDataError("The file only has a header and no data.")
pandas.errors.EmptyDataError: The file only has a header and no data.
'utf-8' codec can't decode byte 0xa3 in position 0: invalid start byte
Traceback (most recent call last):
  File "C:\Users\Michael\PycharmProjects\GFWeatherPipelineTask\weather_pipeline.py", line 46, in import_monthly_weather_csv
    frame_out = pd.read_csv(f"{fpath}", na_values=-99).applymap(
  File "C:\Users\Michael\miniconda3\envs\GF Weather Pipeline Task\lib\site-packages\pandas\io\parsers.py", line 676, in parser_f
    return _read(filepath_or_buffer, kwds)
  File "C:\Users\Michael\miniconda3\envs\GF Weather Pipeline Task\lib\site-packages\pandas\io\parsers.py", line 448, in _read
    parser = TextFileReader(fp_or_buf, **kwds)
  File "C:\Users\Michael\miniconda3\envs\GF Weather Pipeline Task\lib\site-packages\pandas\io\parsers.py", line 880, in __init__
    self._make_engine(self.engine)
  File "C:\Users\Michael\miniconda3\envs\GF Weather Pipeline Task\lib\site-packages\pandas\io\parsers.py", line 1114, in _make_engine
    self._engine = CParserWrapper(self.f, **self.options)
  File "C:\Users\Michael\miniconda3\envs\GF Weather Pipeline Task\lib\site-packages\pandas\io\parsers.py", line 1891, in __init__
    self._reader = parsers.TextReader(src, **kwds)
  File "pandas\_libs\parsers.pyx", line 529, in pandas._libs.parsers.TextReader.__cinit__
  File "pandas\_libs\parsers.pyx", line 749, in pandas._libs.parsers.TextReader._get_header
UnicodeDecodeError: 'utf-8' codec can't decode byte 0xa3 in position 0: invalid start byte
Unexpected column names.
Traceback (most recent call last):
  File "C:\Users\Michael\PycharmProjects\GFWeatherPipelineTask\weather_pipeline.py", line 77, in import_monthly_weather_csv
    raise DataValidationError("Unexpected column names.")
weather_pipeline.DataValidationError: Unexpected column names.
Error tokenizing data. C error: Expected 15 fields in line 3, saw 16
Traceback (most recent call last):
  File "C:\Users\Michael\PycharmProjects\GFWeatherPipelineTask\weather_pipeline.py", line 46, in import_monthly_weather_csv
    frame_out = pd.read_csv(f"{fpath}", na_values=-99).applymap(
  File "C:\Users\Michael\miniconda3\envs\GF Weather Pipeline Task\lib\site-packages\pandas\io\parsers.py", line 676, in parser_f
    return _read(filepath_or_buffer, kwds)
  File "C:\Users\Michael\miniconda3\envs\GF Weather Pipeline Task\lib\site-packages\pandas\io\parsers.py", line 454, in _read
    data = parser.read(nrows)
  File "C:\Users\Michael\miniconda3\envs\GF Weather Pipeline Task\lib\site-packages\pandas\io\parsers.py", line 1133, in read
    ret = self._engine.read(nrows)
  File "C:\Users\Michael\miniconda3\envs\GF Weather Pipeline Task\lib\site-packages\pandas\io\parsers.py", line 2037, in read
    data = self._reader.read(nrows)
  File "pandas\_libs\parsers.pyx", line 860, in pandas._libs.parsers.TextReader.read
  File "pandas\_libs\parsers.pyx", line 875, in pandas._libs.parsers.TextReader._read_low_memory
  File "pandas\_libs\parsers.pyx", line 929, in pandas._libs.parsers.TextReader._read_rows
  File "pandas\_libs\parsers.pyx", line 916, in pandas._libs.parsers.TextReader._tokenize_rows
  File "pandas\_libs\parsers.pyx", line 2071, in pandas._libs.parsers.raise_parser_error
pandas.errors.ParserError: Error tokenizing data. C error: Expected 15 fields in line 3, saw 16

Missing column names or too few row data values.
Traceback (most recent call last):
  File "C:\Users\Michael\PycharmProjects\GFWeatherPipelineTask\weather_pipeline.py", line 72, in import_monthly_weather_csv
    "Missing column names or too few row data values."
weather_pipeline.DataValidationError: Missing column names or too few row data values.
Extra column names or too many row data values.
Traceback (most recent call last):
  File "C:\Users\Michael\PycharmProjects\GFWeatherPipelineTask\weather_pipeline.py", line 75, in import_monthly_weather_csv
    raise DataValidationError("Extra column names or too many row data values.")
weather_pipeline.DataValidationError: Extra column names or too many row data values.
The column ScreenTemperature has a dtype of object which is not a subclass of the required type float64
NoneType: None
The column Longitude has a dtype of object which is not a subclass of the required type float64
NoneType: None
{row: 3, column: "ForecastSiteCode"}: "6" was not in the range [1000, 100000)
NoneType: None
{row: 3, column: "ObservationDate"}: "nan" does not match the date format string "%Y-%m-%dT%H:%M:%S"
NoneType: None
{row: 3, column: "WindDirection"}: "40000" was not in the range [0, 17)
NoneType: None
{row: 3, column: "WindGust"}: "996.0" was not in the range [0, 255)
NoneType: None
{row: 3, column: "ScreenTemperature"}: "KIRKWALL (3017)" was not in the range [-50, 50)
NoneType: None
{row: 3, column: "Pressure"}: "58.95399999999999" was not in the range [870, 1085)
NoneType: None
{row: 3, column: "SignificantWeatherCode"}: "Orkney & Shetland" was not in the range [0, 31)
NoneType: None
{row: 3, column: "Latitude"}: "nan" was not in the range [-90, 90)
NoneType: None
{row: 3, column: "Longitude"}: "nan" was not in the range [-180, 80)
NoneType: None
{row: 6, column: "Longitude"}: "London & South East England" was not in the range [-180, 80)
NoneType: None
{row: 8, column: "ObservationDate"}: "2016-02-07T00:00" does not match the date format string "%Y-%m-%dT%H:%M:%S"
NoneType: None
Data validation failed. Please refer to the log file for detailed information.
Traceback (most recent call last):
  File "C:\Users\Michael\PycharmProjects\GFWeatherPipelineTask\weather_pipeline.py", line 25, in wrapped
    return f(*args, **kwargs)
  File "C:\Users\Michael\PycharmProjects\GFWeatherPipelineTask\weather_pipeline.py", line 204, in validate_weather_data
    "Data validation failed. Please refer to the log file for detailed information."
weather_pipeline.DataValidationError: Data validation failed. Please refer to the log file for detailed information.
TransportError(500, '{\r\n  "errorMessage" : "VALIDATION ERROR: From line 8, column 17 to line 8, column 19: Object \'C:/Users/Michael/PycharmProjects/GFWeatherPipelineTask/Data/wether.parquet\' not found within \'dfs\'\\n\\n\\r\\n[Error Id: 8aeec979-d4f2-4ae1-8f15-2e43c44a1cf3 ]"\r\n}')
Traceback (most recent call last):
  File "C:\Users\Michael\PycharmProjects\GFWeatherPipelineTask\weather_pipeline.py", line 25, in wrapped
    return f(*args, **kwargs)
  File "C:\Users\Michael\PycharmProjects\GFWeatherPipelineTask\weather_pipeline.py", line 354, in query_parquet
    return drill.query(sql, timeout=10)
  File "C:\Users\Michael\miniconda3\envs\GF Weather Pipeline Task\lib\site-packages\pydrill\client\__init__.py", line 62, in query
    'request_timeout': timeout
  File "C:\Users\Michael\miniconda3\envs\GF Weather Pipeline Task\lib\site-packages\pydrill\client\__init__.py", line 24, in perform_request
    return self.transport.perform_request(method, url, params, body)
  File "C:\Users\Michael\miniconda3\envs\GF Weather Pipeline Task\lib\site-packages\pydrill\transport.py", line 79, in perform_request
    timeout=timeout)
  File "C:\Users\Michael\miniconda3\envs\GF Weather Pipeline Task\lib\site-packages\pydrill\connection\requests_conn.py", line 105, in perform_request
    self._raise_error(response.status_code, raw_data)
  File "C:\Users\Michael\miniconda3\envs\GF Weather Pipeline Task\lib\site-packages\pydrill\connection\base.py", line 113, in _raise_error
    raise HTTP_EXCEPTIONS.get(status_code, TransportError)(status_code, error_message, additional_info)
pydrill.exceptions.TransportError: TransportError(500, '{\r\n  "errorMessage" : "VALIDATION ERROR: From line 8, column 17 to line 8, column 19: Object \'C:/Users/Michael/PycharmProjects/GFWeatherPipelineTask/Data/wether.parquet\' not found within \'dfs\'\\n\\n\\r\\n[Error Id: 8aeec979-d4f2-4ae1-8f15-2e43c44a1cf3 ]"\r\n}')
TransportError(500, '{\r\n  "errorMessage" : "VALIDATION ERROR: From line 8, column 17 to line 8, column 19: Object \'C:/Users/Michael/PycharmProjects/GFWeatherPipelineTask/Data/wether.parquet\' not found within \'dfs\'\\n\\n\\r\\n[Error Id: 8aeec979-d4f2-4ae1-8f15-2e43c44a1cf3 ]"\r\n}')
Traceback (most recent call last):
  File "C:\Users\Michael\PycharmProjects\GFWeatherPipelineTask\weather_pipeline.py", line 25, in wrapped
    return f(*args, **kwargs)
  File "C:\Users\Michael\PycharmProjects\GFWeatherPipelineTask\weather_pipeline.py", line 336, in max_daily_average_temperature
    query_out = query_parquet(sql)
  File "C:\Users\Michael\PycharmProjects\GFWeatherPipelineTask\weather_pipeline.py", line 25, in wrapped
    return f(*args, **kwargs)
  File "C:\Users\Michael\PycharmProjects\GFWeatherPipelineTask\weather_pipeline.py", line 354, in query_parquet
    return drill.query(sql, timeout=10)
  File "C:\Users\Michael\miniconda3\envs\GF Weather Pipeline Task\lib\site-packages\pydrill\client\__init__.py", line 62, in query
    'request_timeout': timeout
  File "C:\Users\Michael\miniconda3\envs\GF Weather Pipeline Task\lib\site-packages\pydrill\client\__init__.py", line 24, in perform_request
    return self.transport.perform_request(method, url, params, body)
  File "C:\Users\Michael\miniconda3\envs\GF Weather Pipeline Task\lib\site-packages\pydrill\transport.py", line 79, in perform_request
    timeout=timeout)
  File "C:\Users\Michael\miniconda3\envs\GF Weather Pipeline Task\lib\site-packages\pydrill\connection\requests_conn.py", line 105, in perform_request
    self._raise_error(response.status_code, raw_data)
  File "C:\Users\Michael\miniconda3\envs\GF Weather Pipeline Task\lib\site-packages\pydrill\connection\base.py", line 113, in _raise_error
    raise HTTP_EXCEPTIONS.get(status_code, TransportError)(status_code, error_message, additional_info)
pydrill.exceptions.TransportError: TransportError(500, '{\r\n  "errorMessage" : "VALIDATION ERROR: From line 8, column 17 to line 8, column 19: Object \'C:/Users/Michael/PycharmProjects/GFWeatherPipelineTask/Data/wether.parquet\' not found within \'dfs\'\\n\\n\\r\\n[Error Id: 8aeec979-d4f2-4ae1-8f15-2e43c44a1cf3 ]"\r\n}')
[Errno 2] File  does not exist: ''
Traceback (most recent call last):
  File "C:\Users\Michael\PycharmProjects\GFWeatherPipelineTask\weather_pipeline.py", line 46, in import_monthly_weather_csv
    frame_out = pd.read_csv(f"{fpath}", na_values=-99).applymap(
  File "C:\Users\Michael\miniconda3\envs\GF Weather Pipeline Task\lib\site-packages\pandas\io\parsers.py", line 676, in parser_f
    return _read(filepath_or_buffer, kwds)
  File "C:\Users\Michael\miniconda3\envs\GF Weather Pipeline Task\lib\site-packages\pandas\io\parsers.py", line 448, in _read
    parser = TextFileReader(fp_or_buf, **kwds)
  File "C:\Users\Michael\miniconda3\envs\GF Weather Pipeline Task\lib\site-packages\pandas\io\parsers.py", line 880, in __init__
    self._make_engine(self.engine)
  File "C:\Users\Michael\miniconda3\envs\GF Weather Pipeline Task\lib\site-packages\pandas\io\parsers.py", line 1114, in _make_engine
    self._engine = CParserWrapper(self.f, **self.options)
  File "C:\Users\Michael\miniconda3\envs\GF Weather Pipeline Task\lib\site-packages\pandas\io\parsers.py", line 1891, in __init__
    self._reader = parsers.TextReader(src, **kwds)
  File "pandas\_libs\parsers.pyx", line 374, in pandas._libs.parsers.TextReader.__cinit__
  File "pandas\_libs\parsers.pyx", line 674, in pandas._libs.parsers.TextReader._setup_parser_source
FileNotFoundError: [Errno 2] File  does not exist: ''
No columns to parse from file
Traceback (most recent call last):
  File "C:\Users\Michael\PycharmProjects\GFWeatherPipelineTask\weather_pipeline.py", line 46, in import_monthly_weather_csv
    frame_out = pd.read_csv(f"{fpath}", na_values=-99).applymap(
  File "C:\Users\Michael\miniconda3\envs\GF Weather Pipeline Task\lib\site-packages\pandas\io\parsers.py", line 676, in parser_f
    return _read(filepath_or_buffer, kwds)
  File "C:\Users\Michael\miniconda3\envs\GF Weather Pipeline Task\lib\site-packages\pandas\io\parsers.py", line 448, in _read
    parser = TextFileReader(fp_or_buf, **kwds)
  File "C:\Users\Michael\miniconda3\envs\GF Weather Pipeline Task\lib\site-packages\pandas\io\parsers.py", line 880, in __init__
    self._make_engine(self.engine)
  File "C:\Users\Michael\miniconda3\envs\GF Weather Pipeline Task\lib\site-packages\pandas\io\parsers.py", line 1114, in _make_engine
    self._engine = CParserWrapper(self.f, **self.options)
  File "C:\Users\Michael\miniconda3\envs\GF Weather Pipeline Task\lib\site-packages\pandas\io\parsers.py", line 1891, in __init__
    self._reader = parsers.TextReader(src, **kwds)
  File "pandas\_libs\parsers.pyx", line 532, in pandas._libs.parsers.TextReader.__cinit__
pandas.errors.EmptyDataError: No columns to parse from file
The file only has a header and no data.
Traceback (most recent call last):
  File "C:\Users\Michael\PycharmProjects\GFWeatherPipelineTask\weather_pipeline.py", line 69, in import_monthly_weather_csv
    raise pd.errors.EmptyDataError("The file only has a header and no data.")
pandas.errors.EmptyDataError: The file only has a header and no data.
'utf-8' codec can't decode byte 0xa3 in position 0: invalid start byte
Traceback (most recent call last):
  File "C:\Users\Michael\PycharmProjects\GFWeatherPipelineTask\weather_pipeline.py", line 46, in import_monthly_weather_csv
    frame_out = pd.read_csv(f"{fpath}", na_values=-99).applymap(
  File "C:\Users\Michael\miniconda3\envs\GF Weather Pipeline Task\lib\site-packages\pandas\io\parsers.py", line 676, in parser_f
    return _read(filepath_or_buffer, kwds)
  File "C:\Users\Michael\miniconda3\envs\GF Weather Pipeline Task\lib\site-packages\pandas\io\parsers.py", line 448, in _read
    parser = TextFileReader(fp_or_buf, **kwds)
  File "C:\Users\Michael\miniconda3\envs\GF Weather Pipeline Task\lib\site-packages\pandas\io\parsers.py", line 880, in __init__
    self._make_engine(self.engine)
  File "C:\Users\Michael\miniconda3\envs\GF Weather Pipeline Task\lib\site-packages\pandas\io\parsers.py", line 1114, in _make_engine
    self._engine = CParserWrapper(self.f, **self.options)
  File "C:\Users\Michael\miniconda3\envs\GF Weather Pipeline Task\lib\site-packages\pandas\io\parsers.py", line 1891, in __init__
    self._reader = parsers.TextReader(src, **kwds)
  File "pandas\_libs\parsers.pyx", line 529, in pandas._libs.parsers.TextReader.__cinit__
  File "pandas\_libs\parsers.pyx", line 749, in pandas._libs.parsers.TextReader._get_header
UnicodeDecodeError: 'utf-8' codec can't decode byte 0xa3 in position 0: invalid start byte
Unexpected column names.
Traceback (most recent call last):
  File "C:\Users\Michael\PycharmProjects\GFWeatherPipelineTask\weather_pipeline.py", line 77, in import_monthly_weather_csv
    raise DataValidationError("Unexpected column names.")
weather_pipeline.DataValidationError: Unexpected column names.
Error tokenizing data. C error: Expected 15 fields in line 3, saw 16
Traceback (most recent call last):
  File "C:\Users\Michael\PycharmProjects\GFWeatherPipelineTask\weather_pipeline.py", line 46, in import_monthly_weather_csv
    frame_out = pd.read_csv(f"{fpath}", na_values=-99).applymap(
  File "C:\Users\Michael\miniconda3\envs\GF Weather Pipeline Task\lib\site-packages\pandas\io\parsers.py", line 676, in parser_f
    return _read(filepath_or_buffer, kwds)
  File "C:\Users\Michael\miniconda3\envs\GF Weather Pipeline Task\lib\site-packages\pandas\io\parsers.py", line 454, in _read
    data = parser.read(nrows)
  File "C:\Users\Michael\miniconda3\envs\GF Weather Pipeline Task\lib\site-packages\pandas\io\parsers.py", line 1133, in read
    ret = self._engine.read(nrows)
  File "C:\Users\Michael\miniconda3\envs\GF Weather Pipeline Task\lib\site-packages\pandas\io\parsers.py", line 2037, in read
    data = self._reader.read(nrows)
  File "pandas\_libs\parsers.pyx", line 860, in pandas._libs.parsers.TextReader.read
  File "pandas\_libs\parsers.pyx", line 875, in pandas._libs.parsers.TextReader._read_low_memory
  File "pandas\_libs\parsers.pyx", line 929, in pandas._libs.parsers.TextReader._read_rows
  File "pandas\_libs\parsers.pyx", line 916, in pandas._libs.parsers.TextReader._tokenize_rows
  File "pandas\_libs\parsers.pyx", line 2071, in pandas._libs.parsers.raise_parser_error
pandas.errors.ParserError: Error tokenizing data. C error: Expected 15 fields in line 3, saw 16

Missing column names or too few row data values.
Traceback (most recent call last):
  File "C:\Users\Michael\PycharmProjects\GFWeatherPipelineTask\weather_pipeline.py", line 72, in import_monthly_weather_csv
    "Missing column names or too few row data values."
weather_pipeline.DataValidationError: Missing column names or too few row data values.
Extra column names or too many row data values.
Traceback (most recent call last):
  File "C:\Users\Michael\PycharmProjects\GFWeatherPipelineTask\weather_pipeline.py", line 75, in import_monthly_weather_csv
    raise DataValidationError("Extra column names or too many row data values.")
weather_pipeline.DataValidationError: Extra column names or too many row data values.
The column ScreenTemperature has a dtype of object which is not a subclass of the required type float64
NoneType: None
The column Longitude has a dtype of object which is not a subclass of the required type float64
NoneType: None
{row: 3, column: "ForecastSiteCode"}: "6" was not in the range [1000, 100000)
NoneType: None
{row: 3, column: "ObservationDate"}: "nan" does not match the date format string "%Y-%m-%dT%H:%M:%S"
NoneType: None
{row: 3, column: "WindDirection"}: "40000" was not in the range [0, 17)
NoneType: None
{row: 3, column: "WindGust"}: "996.0" was not in the range [0, 255)
NoneType: None
{row: 3, column: "ScreenTemperature"}: "KIRKWALL (3017)" was not in the range [-50, 50)
NoneType: None
{row: 3, column: "Pressure"}: "58.95399999999999" was not in the range [870, 1085)
NoneType: None
{row: 3, column: "SignificantWeatherCode"}: "Orkney & Shetland" was not in the range [0, 31)
NoneType: None
{row: 3, column: "Latitude"}: "nan" was not in the range [-90, 90)
NoneType: None
{row: 3, column: "Longitude"}: "nan" was not in the range [-180, 80)
NoneType: None
{row: 6, column: "Longitude"}: "London & South East England" was not in the range [-180, 80)
NoneType: None
{row: 8, column: "ObservationDate"}: "2016-02-07T00:00" does not match the date format string "%Y-%m-%dT%H:%M:%S"
NoneType: None
Data validation failed. Please refer to the log file for detailed information.
Traceback (most recent call last):
  File "C:\Users\Michael\PycharmProjects\GFWeatherPipelineTask\weather_pipeline.py", line 25, in wrapped
    return f(*args, **kwargs)
  File "C:\Users\Michael\PycharmProjects\GFWeatherPipelineTask\weather_pipeline.py", line 204, in validate_weather_data
    "Data validation failed. Please refer to the log file for detailed information."
weather_pipeline.DataValidationError: Data validation failed. Please refer to the log file for detailed information.
TransportError(500, '{\r\n  "errorMessage" : "VALIDATION ERROR: From line 8, column 17 to line 8, column 19: Object \'C:/Users/Michael/PycharmProjects/GFWeatherPipelineTask/Data/wether.parquet\' not found within \'dfs\'\\n\\n\\r\\n[Error Id: 4c304a3a-b529-431a-9341-5e066c0e3186 ]"\r\n}')
Traceback (most recent call last):
  File "C:\Users\Michael\PycharmProjects\GFWeatherPipelineTask\weather_pipeline.py", line 25, in wrapped
    return f(*args, **kwargs)
  File "C:\Users\Michael\PycharmProjects\GFWeatherPipelineTask\weather_pipeline.py", line 354, in query_parquet
    return drill.query(sql, timeout=10)
  File "C:\Users\Michael\miniconda3\envs\GF Weather Pipeline Task\lib\site-packages\pydrill\client\__init__.py", line 62, in query
    'request_timeout': timeout
  File "C:\Users\Michael\miniconda3\envs\GF Weather Pipeline Task\lib\site-packages\pydrill\client\__init__.py", line 24, in perform_request
    return self.transport.perform_request(method, url, params, body)
  File "C:\Users\Michael\miniconda3\envs\GF Weather Pipeline Task\lib\site-packages\pydrill\transport.py", line 79, in perform_request
    timeout=timeout)
  File "C:\Users\Michael\miniconda3\envs\GF Weather Pipeline Task\lib\site-packages\pydrill\connection\requests_conn.py", line 105, in perform_request
    self._raise_error(response.status_code, raw_data)
  File "C:\Users\Michael\miniconda3\envs\GF Weather Pipeline Task\lib\site-packages\pydrill\connection\base.py", line 113, in _raise_error
    raise HTTP_EXCEPTIONS.get(status_code, TransportError)(status_code, error_message, additional_info)
pydrill.exceptions.TransportError: TransportError(500, '{\r\n  "errorMessage" : "VALIDATION ERROR: From line 8, column 17 to line 8, column 19: Object \'C:/Users/Michael/PycharmProjects/GFWeatherPipelineTask/Data/wether.parquet\' not found within \'dfs\'\\n\\n\\r\\n[Error Id: 4c304a3a-b529-431a-9341-5e066c0e3186 ]"\r\n}')
TransportError(500, '{\r\n  "errorMessage" : "VALIDATION ERROR: From line 8, column 17 to line 8, column 19: Object \'C:/Users/Michael/PycharmProjects/GFWeatherPipelineTask/Data/wether.parquet\' not found within \'dfs\'\\n\\n\\r\\n[Error Id: 4c304a3a-b529-431a-9341-5e066c0e3186 ]"\r\n}')
Traceback (most recent call last):
  File "C:\Users\Michael\PycharmProjects\GFWeatherPipelineTask\weather_pipeline.py", line 25, in wrapped
    return f(*args, **kwargs)
  File "C:\Users\Michael\PycharmProjects\GFWeatherPipelineTask\weather_pipeline.py", line 336, in max_daily_average_temperature
    query_out = query_parquet(sql)
  File "C:\Users\Michael\PycharmProjects\GFWeatherPipelineTask\weather_pipeline.py", line 25, in wrapped
    return f(*args, **kwargs)
  File "C:\Users\Michael\PycharmProjects\GFWeatherPipelineTask\weather_pipeline.py", line 354, in query_parquet
    return drill.query(sql, timeout=10)
  File "C:\Users\Michael\miniconda3\envs\GF Weather Pipeline Task\lib\site-packages\pydrill\client\__init__.py", line 62, in query
    'request_timeout': timeout
  File "C:\Users\Michael\miniconda3\envs\GF Weather Pipeline Task\lib\site-packages\pydrill\client\__init__.py", line 24, in perform_request
    return self.transport.perform_request(method, url, params, body)
  File "C:\Users\Michael\miniconda3\envs\GF Weather Pipeline Task\lib\site-packages\pydrill\transport.py", line 79, in perform_request
    timeout=timeout)
  File "C:\Users\Michael\miniconda3\envs\GF Weather Pipeline Task\lib\site-packages\pydrill\connection\requests_conn.py", line 105, in perform_request
    self._raise_error(response.status_code, raw_data)
  File "C:\Users\Michael\miniconda3\envs\GF Weather Pipeline Task\lib\site-packages\pydrill\connection\base.py", line 113, in _raise_error
    raise HTTP_EXCEPTIONS.get(status_code, TransportError)(status_code, error_message, additional_info)
pydrill.exceptions.TransportError: TransportError(500, '{\r\n  "errorMessage" : "VALIDATION ERROR: From line 8, column 17 to line 8, column 19: Object \'C:/Users/Michael/PycharmProjects/GFWeatherPipelineTask/Data/wether.parquet\' not found within \'dfs\'\\n\\n\\r\\n[Error Id: 4c304a3a-b529-431a-9341-5e066c0e3186 ]"\r\n}')
[Errno 2] File  does not exist: ''
Traceback (most recent call last):
  File "C:\Users\Michael\PycharmProjects\GFWeatherPipelineTask\weather_pipeline.py", line 46, in import_monthly_weather_csv
    frame_out = pd.read_csv(f"{fpath}", na_values=-99).applymap(
  File "C:\Users\Michael\miniconda3\envs\GF Weather Pipeline Task\lib\site-packages\pandas\io\parsers.py", line 676, in parser_f
    return _read(filepath_or_buffer, kwds)
  File "C:\Users\Michael\miniconda3\envs\GF Weather Pipeline Task\lib\site-packages\pandas\io\parsers.py", line 448, in _read
    parser = TextFileReader(fp_or_buf, **kwds)
  File "C:\Users\Michael\miniconda3\envs\GF Weather Pipeline Task\lib\site-packages\pandas\io\parsers.py", line 880, in __init__
    self._make_engine(self.engine)
  File "C:\Users\Michael\miniconda3\envs\GF Weather Pipeline Task\lib\site-packages\pandas\io\parsers.py", line 1114, in _make_engine
    self._engine = CParserWrapper(self.f, **self.options)
  File "C:\Users\Michael\miniconda3\envs\GF Weather Pipeline Task\lib\site-packages\pandas\io\parsers.py", line 1891, in __init__
    self._reader = parsers.TextReader(src, **kwds)
  File "pandas\_libs\parsers.pyx", line 374, in pandas._libs.parsers.TextReader.__cinit__
  File "pandas\_libs\parsers.pyx", line 674, in pandas._libs.parsers.TextReader._setup_parser_source
FileNotFoundError: [Errno 2] File  does not exist: ''
No columns to parse from file
Traceback (most recent call last):
  File "C:\Users\Michael\PycharmProjects\GFWeatherPipelineTask\weather_pipeline.py", line 46, in import_monthly_weather_csv
    frame_out = pd.read_csv(f"{fpath}", na_values=-99).applymap(
  File "C:\Users\Michael\miniconda3\envs\GF Weather Pipeline Task\lib\site-packages\pandas\io\parsers.py", line 676, in parser_f
    return _read(filepath_or_buffer, kwds)
  File "C:\Users\Michael\miniconda3\envs\GF Weather Pipeline Task\lib\site-packages\pandas\io\parsers.py", line 448, in _read
    parser = TextFileReader(fp_or_buf, **kwds)
  File "C:\Users\Michael\miniconda3\envs\GF Weather Pipeline Task\lib\site-packages\pandas\io\parsers.py", line 880, in __init__
    self._make_engine(self.engine)
  File "C:\Users\Michael\miniconda3\envs\GF Weather Pipeline Task\lib\site-packages\pandas\io\parsers.py", line 1114, in _make_engine
    self._engine = CParserWrapper(self.f, **self.options)
  File "C:\Users\Michael\miniconda3\envs\GF Weather Pipeline Task\lib\site-packages\pandas\io\parsers.py", line 1891, in __init__
    self._reader = parsers.TextReader(src, **kwds)
  File "pandas\_libs\parsers.pyx", line 532, in pandas._libs.parsers.TextReader.__cinit__
pandas.errors.EmptyDataError: No columns to parse from file
The file only has a header and no data.
Traceback (most recent call last):
  File "C:\Users\Michael\PycharmProjects\GFWeatherPipelineTask\weather_pipeline.py", line 69, in import_monthly_weather_csv
    raise pd.errors.EmptyDataError("The file only has a header and no data.")
pandas.errors.EmptyDataError: The file only has a header and no data.
'utf-8' codec can't decode byte 0xa3 in position 0: invalid start byte
Traceback (most recent call last):
  File "C:\Users\Michael\PycharmProjects\GFWeatherPipelineTask\weather_pipeline.py", line 46, in import_monthly_weather_csv
    frame_out = pd.read_csv(f"{fpath}", na_values=-99).applymap(
  File "C:\Users\Michael\miniconda3\envs\GF Weather Pipeline Task\lib\site-packages\pandas\io\parsers.py", line 676, in parser_f
    return _read(filepath_or_buffer, kwds)
  File "C:\Users\Michael\miniconda3\envs\GF Weather Pipeline Task\lib\site-packages\pandas\io\parsers.py", line 448, in _read
    parser = TextFileReader(fp_or_buf, **kwds)
  File "C:\Users\Michael\miniconda3\envs\GF Weather Pipeline Task\lib\site-packages\pandas\io\parsers.py", line 880, in __init__
    self._make_engine(self.engine)
  File "C:\Users\Michael\miniconda3\envs\GF Weather Pipeline Task\lib\site-packages\pandas\io\parsers.py", line 1114, in _make_engine
    self._engine = CParserWrapper(self.f, **self.options)
  File "C:\Users\Michael\miniconda3\envs\GF Weather Pipeline Task\lib\site-packages\pandas\io\parsers.py", line 1891, in __init__
    self._reader = parsers.TextReader(src, **kwds)
  File "pandas\_libs\parsers.pyx", line 529, in pandas._libs.parsers.TextReader.__cinit__
  File "pandas\_libs\parsers.pyx", line 749, in pandas._libs.parsers.TextReader._get_header
UnicodeDecodeError: 'utf-8' codec can't decode byte 0xa3 in position 0: invalid start byte
Unexpected column names.
Traceback (most recent call last):
  File "C:\Users\Michael\PycharmProjects\GFWeatherPipelineTask\weather_pipeline.py", line 77, in import_monthly_weather_csv
    raise DataValidationError("Unexpected column names.")
weather_pipeline.DataValidationError: Unexpected column names.
Error tokenizing data. C error: Expected 15 fields in line 3, saw 16
Traceback (most recent call last):
  File "C:\Users\Michael\PycharmProjects\GFWeatherPipelineTask\weather_pipeline.py", line 46, in import_monthly_weather_csv
    frame_out = pd.read_csv(f"{fpath}", na_values=-99).applymap(
  File "C:\Users\Michael\miniconda3\envs\GF Weather Pipeline Task\lib\site-packages\pandas\io\parsers.py", line 676, in parser_f
    return _read(filepath_or_buffer, kwds)
  File "C:\Users\Michael\miniconda3\envs\GF Weather Pipeline Task\lib\site-packages\pandas\io\parsers.py", line 454, in _read
    data = parser.read(nrows)
  File "C:\Users\Michael\miniconda3\envs\GF Weather Pipeline Task\lib\site-packages\pandas\io\parsers.py", line 1133, in read
    ret = self._engine.read(nrows)
  File "C:\Users\Michael\miniconda3\envs\GF Weather Pipeline Task\lib\site-packages\pandas\io\parsers.py", line 2037, in read
    data = self._reader.read(nrows)
  File "pandas\_libs\parsers.pyx", line 860, in pandas._libs.parsers.TextReader.read
  File "pandas\_libs\parsers.pyx", line 875, in pandas._libs.parsers.TextReader._read_low_memory
  File "pandas\_libs\parsers.pyx", line 929, in pandas._libs.parsers.TextReader._read_rows
  File "pandas\_libs\parsers.pyx", line 916, in pandas._libs.parsers.TextReader._tokenize_rows
  File "pandas\_libs\parsers.pyx", line 2071, in pandas._libs.parsers.raise_parser_error
pandas.errors.ParserError: Error tokenizing data. C error: Expected 15 fields in line 3, saw 16

Missing column names or too few row data values.
Traceback (most recent call last):
  File "C:\Users\Michael\PycharmProjects\GFWeatherPipelineTask\weather_pipeline.py", line 72, in import_monthly_weather_csv
    "Missing column names or too few row data values."
weather_pipeline.DataValidationError: Missing column names or too few row data values.
Extra column names or too many row data values.
Traceback (most recent call last):
  File "C:\Users\Michael\PycharmProjects\GFWeatherPipelineTask\weather_pipeline.py", line 75, in import_monthly_weather_csv
    raise DataValidationError("Extra column names or too many row data values.")
weather_pipeline.DataValidationError: Extra column names or too many row data values.
The column ScreenTemperature has a dtype of object which is not a subclass of the required type float64
NoneType: None
The column Longitude has a dtype of object which is not a subclass of the required type float64
NoneType: None
{row: 3, column: "ForecastSiteCode"}: "6" was not in the range [1000, 100000)
NoneType: None
{row: 3, column: "ObservationDate"}: "nan" does not match the date format string "%Y-%m-%dT%H:%M:%S"
NoneType: None
{row: 3, column: "WindDirection"}: "40000" was not in the range [0, 17)
NoneType: None
{row: 3, column: "WindGust"}: "996.0" was not in the range [0, 255)
NoneType: None
{row: 3, column: "ScreenTemperature"}: "KIRKWALL (3017)" was not in the range [-50, 50)
NoneType: None
{row: 3, column: "Pressure"}: "58.95399999999999" was not in the range [870, 1085)
NoneType: None
{row: 3, column: "SignificantWeatherCode"}: "Orkney & Shetland" was not in the range [0, 31)
NoneType: None
{row: 3, column: "Latitude"}: "nan" was not in the range [-90, 90)
NoneType: None
{row: 3, column: "Longitude"}: "nan" was not in the range [-180, 80)
NoneType: None
{row: 6, column: "Longitude"}: "London & South East England" was not in the range [-180, 80)
NoneType: None
{row: 8, column: "ObservationDate"}: "2016-02-07T00:00" does not match the date format string "%Y-%m-%dT%H:%M:%S"
NoneType: None
Data validation failed. Please refer to the log file for detailed information.
Traceback (most recent call last):
  File "C:\Users\Michael\PycharmProjects\GFWeatherPipelineTask\weather_pipeline.py", line 25, in wrapped
    return f(*args, **kwargs)
  File "C:\Users\Michael\PycharmProjects\GFWeatherPipelineTask\weather_pipeline.py", line 204, in validate_weather_data
    "Data validation failed. Please refer to the log file for detailed information."
weather_pipeline.DataValidationError: Data validation failed. Please refer to the log file for detailed information.
TransportError(500, '{\r\n  "errorMessage" : "VALIDATION ERROR: From line 8, column 17 to line 8, column 19: Object \'C:/Users/Michael/PycharmProjects/GFWeatherPipelineTask/Data/wether.parquet\' not found within \'dfs\'\\n\\n\\r\\n[Error Id: f0ccb024-48c6-482a-9b84-e5a23a4d18ef ]"\r\n}')
Traceback (most recent call last):
  File "C:\Users\Michael\PycharmProjects\GFWeatherPipelineTask\weather_pipeline.py", line 25, in wrapped
    return f(*args, **kwargs)
  File "C:\Users\Michael\PycharmProjects\GFWeatherPipelineTask\weather_pipeline.py", line 354, in query_parquet
    return drill.query(sql, timeout=10)
  File "C:\Users\Michael\miniconda3\envs\GF Weather Pipeline Task\lib\site-packages\pydrill\client\__init__.py", line 62, in query
    'request_timeout': timeout
  File "C:\Users\Michael\miniconda3\envs\GF Weather Pipeline Task\lib\site-packages\pydrill\client\__init__.py", line 24, in perform_request
    return self.transport.perform_request(method, url, params, body)
  File "C:\Users\Michael\miniconda3\envs\GF Weather Pipeline Task\lib\site-packages\pydrill\transport.py", line 79, in perform_request
    timeout=timeout)
  File "C:\Users\Michael\miniconda3\envs\GF Weather Pipeline Task\lib\site-packages\pydrill\connection\requests_conn.py", line 105, in perform_request
    self._raise_error(response.status_code, raw_data)
  File "C:\Users\Michael\miniconda3\envs\GF Weather Pipeline Task\lib\site-packages\pydrill\connection\base.py", line 113, in _raise_error
    raise HTTP_EXCEPTIONS.get(status_code, TransportError)(status_code, error_message, additional_info)
pydrill.exceptions.TransportError: TransportError(500, '{\r\n  "errorMessage" : "VALIDATION ERROR: From line 8, column 17 to line 8, column 19: Object \'C:/Users/Michael/PycharmProjects/GFWeatherPipelineTask/Data/wether.parquet\' not found within \'dfs\'\\n\\n\\r\\n[Error Id: f0ccb024-48c6-482a-9b84-e5a23a4d18ef ]"\r\n}')
TransportError(500, '{\r\n  "errorMessage" : "VALIDATION ERROR: From line 8, column 17 to line 8, column 19: Object \'C:/Users/Michael/PycharmProjects/GFWeatherPipelineTask/Data/wether.parquet\' not found within \'dfs\'\\n\\n\\r\\n[Error Id: f0ccb024-48c6-482a-9b84-e5a23a4d18ef ]"\r\n}')
Traceback (most recent call last):
  File "C:\Users\Michael\PycharmProjects\GFWeatherPipelineTask\weather_pipeline.py", line 25, in wrapped
    return f(*args, **kwargs)
  File "C:\Users\Michael\PycharmProjects\GFWeatherPipelineTask\weather_pipeline.py", line 336, in max_daily_average_temperature
    query_out = query_parquet(sql)
  File "C:\Users\Michael\PycharmProjects\GFWeatherPipelineTask\weather_pipeline.py", line 25, in wrapped
    return f(*args, **kwargs)
  File "C:\Users\Michael\PycharmProjects\GFWeatherPipelineTask\weather_pipeline.py", line 354, in query_parquet
    return drill.query(sql, timeout=10)
  File "C:\Users\Michael\miniconda3\envs\GF Weather Pipeline Task\lib\site-packages\pydrill\client\__init__.py", line 62, in query
    'request_timeout': timeout
  File "C:\Users\Michael\miniconda3\envs\GF Weather Pipeline Task\lib\site-packages\pydrill\client\__init__.py", line 24, in perform_request
    return self.transport.perform_request(method, url, params, body)
  File "C:\Users\Michael\miniconda3\envs\GF Weather Pipeline Task\lib\site-packages\pydrill\transport.py", line 79, in perform_request
    timeout=timeout)
  File "C:\Users\Michael\miniconda3\envs\GF Weather Pipeline Task\lib\site-packages\pydrill\connection\requests_conn.py", line 105, in perform_request
    self._raise_error(response.status_code, raw_data)
  File "C:\Users\Michael\miniconda3\envs\GF Weather Pipeline Task\lib\site-packages\pydrill\connection\base.py", line 113, in _raise_error
    raise HTTP_EXCEPTIONS.get(status_code, TransportError)(status_code, error_message, additional_info)
pydrill.exceptions.TransportError: TransportError(500, '{\r\n  "errorMessage" : "VALIDATION ERROR: From line 8, column 17 to line 8, column 19: Object \'C:/Users/Michael/PycharmProjects/GFWeatherPipelineTask/Data/wether.parquet\' not found within \'dfs\'\\n\\n\\r\\n[Error Id: f0ccb024-48c6-482a-9b84-e5a23a4d18ef ]"\r\n}')
[Errno 2] File  does not exist: ''
Traceback (most recent call last):
  File "C:\Users\Michael\PycharmProjects\GFWeatherPipelineTask\weather_pipeline.py", line 46, in import_monthly_weather_csv
    frame_out = pd.read_csv(f"{fpath}", na_values=-99).applymap(
  File "C:\Users\Michael\miniconda3\envs\GF Weather Pipeline Task\lib\site-packages\pandas\io\parsers.py", line 676, in parser_f
    return _read(filepath_or_buffer, kwds)
  File "C:\Users\Michael\miniconda3\envs\GF Weather Pipeline Task\lib\site-packages\pandas\io\parsers.py", line 448, in _read
    parser = TextFileReader(fp_or_buf, **kwds)
  File "C:\Users\Michael\miniconda3\envs\GF Weather Pipeline Task\lib\site-packages\pandas\io\parsers.py", line 880, in __init__
    self._make_engine(self.engine)
  File "C:\Users\Michael\miniconda3\envs\GF Weather Pipeline Task\lib\site-packages\pandas\io\parsers.py", line 1114, in _make_engine
    self._engine = CParserWrapper(self.f, **self.options)
  File "C:\Users\Michael\miniconda3\envs\GF Weather Pipeline Task\lib\site-packages\pandas\io\parsers.py", line 1891, in __init__
    self._reader = parsers.TextReader(src, **kwds)
  File "pandas\_libs\parsers.pyx", line 374, in pandas._libs.parsers.TextReader.__cinit__
  File "pandas\_libs\parsers.pyx", line 674, in pandas._libs.parsers.TextReader._setup_parser_source
FileNotFoundError: [Errno 2] File  does not exist: ''
No columns to parse from file
Traceback (most recent call last):
  File "C:\Users\Michael\PycharmProjects\GFWeatherPipelineTask\weather_pipeline.py", line 46, in import_monthly_weather_csv
    frame_out = pd.read_csv(f"{fpath}", na_values=-99).applymap(
  File "C:\Users\Michael\miniconda3\envs\GF Weather Pipeline Task\lib\site-packages\pandas\io\parsers.py", line 676, in parser_f
    return _read(filepath_or_buffer, kwds)
  File "C:\Users\Michael\miniconda3\envs\GF Weather Pipeline Task\lib\site-packages\pandas\io\parsers.py", line 448, in _read
    parser = TextFileReader(fp_or_buf, **kwds)
  File "C:\Users\Michael\miniconda3\envs\GF Weather Pipeline Task\lib\site-packages\pandas\io\parsers.py", line 880, in __init__
    self._make_engine(self.engine)
  File "C:\Users\Michael\miniconda3\envs\GF Weather Pipeline Task\lib\site-packages\pandas\io\parsers.py", line 1114, in _make_engine
    self._engine = CParserWrapper(self.f, **self.options)
  File "C:\Users\Michael\miniconda3\envs\GF Weather Pipeline Task\lib\site-packages\pandas\io\parsers.py", line 1891, in __init__
    self._reader = parsers.TextReader(src, **kwds)
  File "pandas\_libs\parsers.pyx", line 532, in pandas._libs.parsers.TextReader.__cinit__
pandas.errors.EmptyDataError: No columns to parse from file
The file only has a header and no data.
Traceback (most recent call last):
  File "C:\Users\Michael\PycharmProjects\GFWeatherPipelineTask\weather_pipeline.py", line 69, in import_monthly_weather_csv
    raise pd.errors.EmptyDataError("The file only has a header and no data.")
pandas.errors.EmptyDataError: The file only has a header and no data.
'utf-8' codec can't decode byte 0xa3 in position 0: invalid start byte
Traceback (most recent call last):
  File "C:\Users\Michael\PycharmProjects\GFWeatherPipelineTask\weather_pipeline.py", line 46, in import_monthly_weather_csv
    frame_out = pd.read_csv(f"{fpath}", na_values=-99).applymap(
  File "C:\Users\Michael\miniconda3\envs\GF Weather Pipeline Task\lib\site-packages\pandas\io\parsers.py", line 676, in parser_f
    return _read(filepath_or_buffer, kwds)
  File "C:\Users\Michael\miniconda3\envs\GF Weather Pipeline Task\lib\site-packages\pandas\io\parsers.py", line 448, in _read
    parser = TextFileReader(fp_or_buf, **kwds)
  File "C:\Users\Michael\miniconda3\envs\GF Weather Pipeline Task\lib\site-packages\pandas\io\parsers.py", line 880, in __init__
    self._make_engine(self.engine)
  File "C:\Users\Michael\miniconda3\envs\GF Weather Pipeline Task\lib\site-packages\pandas\io\parsers.py", line 1114, in _make_engine
    self._engine = CParserWrapper(self.f, **self.options)
  File "C:\Users\Michael\miniconda3\envs\GF Weather Pipeline Task\lib\site-packages\pandas\io\parsers.py", line 1891, in __init__
    self._reader = parsers.TextReader(src, **kwds)
  File "pandas\_libs\parsers.pyx", line 529, in pandas._libs.parsers.TextReader.__cinit__
  File "pandas\_libs\parsers.pyx", line 749, in pandas._libs.parsers.TextReader._get_header
UnicodeDecodeError: 'utf-8' codec can't decode byte 0xa3 in position 0: invalid start byte
Unexpected column names.
Traceback (most recent call last):
  File "C:\Users\Michael\PycharmProjects\GFWeatherPipelineTask\weather_pipeline.py", line 77, in import_monthly_weather_csv
    raise DataValidationError("Unexpected column names.")
weather_pipeline.DataValidationError: Unexpected column names.
Error tokenizing data. C error: Expected 15 fields in line 3, saw 16
Traceback (most recent call last):
  File "C:\Users\Michael\PycharmProjects\GFWeatherPipelineTask\weather_pipeline.py", line 46, in import_monthly_weather_csv
    frame_out = pd.read_csv(f"{fpath}", na_values=-99).applymap(
  File "C:\Users\Michael\miniconda3\envs\GF Weather Pipeline Task\lib\site-packages\pandas\io\parsers.py", line 676, in parser_f
    return _read(filepath_or_buffer, kwds)
  File "C:\Users\Michael\miniconda3\envs\GF Weather Pipeline Task\lib\site-packages\pandas\io\parsers.py", line 454, in _read
    data = parser.read(nrows)
  File "C:\Users\Michael\miniconda3\envs\GF Weather Pipeline Task\lib\site-packages\pandas\io\parsers.py", line 1133, in read
    ret = self._engine.read(nrows)
  File "C:\Users\Michael\miniconda3\envs\GF Weather Pipeline Task\lib\site-packages\pandas\io\parsers.py", line 2037, in read
    data = self._reader.read(nrows)
  File "pandas\_libs\parsers.pyx", line 860, in pandas._libs.parsers.TextReader.read
  File "pandas\_libs\parsers.pyx", line 875, in pandas._libs.parsers.TextReader._read_low_memory
  File "pandas\_libs\parsers.pyx", line 929, in pandas._libs.parsers.TextReader._read_rows
  File "pandas\_libs\parsers.pyx", line 916, in pandas._libs.parsers.TextReader._tokenize_rows
  File "pandas\_libs\parsers.pyx", line 2071, in pandas._libs.parsers.raise_parser_error
pandas.errors.ParserError: Error tokenizing data. C error: Expected 15 fields in line 3, saw 16

Missing column names or too few row data values.
Traceback (most recent call last):
  File "C:\Users\Michael\PycharmProjects\GFWeatherPipelineTask\weather_pipeline.py", line 72, in import_monthly_weather_csv
    "Missing column names or too few row data values."
weather_pipeline.DataValidationError: Missing column names or too few row data values.
Extra column names or too many row data values.
Traceback (most recent call last):
  File "C:\Users\Michael\PycharmProjects\GFWeatherPipelineTask\weather_pipeline.py", line 75, in import_monthly_weather_csv
    raise DataValidationError("Extra column names or too many row data values.")
weather_pipeline.DataValidationError: Extra column names or too many row data values.
The column ScreenTemperature has a dtype of object which is not a subclass of the required type float64
NoneType: None
The column Longitude has a dtype of object which is not a subclass of the required type float64
NoneType: None
{row: 3, column: "ForecastSiteCode"}: "6" was not in the range [1000, 100000)
NoneType: None
{row: 3, column: "ObservationDate"}: "nan" does not match the date format string "%Y-%m-%dT%H:%M:%S"
NoneType: None
{row: 3, column: "WindDirection"}: "40000" was not in the range [0, 17)
NoneType: None
{row: 3, column: "WindGust"}: "996.0" was not in the range [0, 255)
NoneType: None
{row: 3, column: "ScreenTemperature"}: "KIRKWALL (3017)" was not in the range [-50, 50)
NoneType: None
{row: 3, column: "Pressure"}: "58.95399999999999" was not in the range [870, 1085)
NoneType: None
{row: 3, column: "SignificantWeatherCode"}: "Orkney & Shetland" was not in the range [0, 31)
NoneType: None
{row: 3, column: "Latitude"}: "nan" was not in the range [-90, 90)
NoneType: None
{row: 3, column: "Longitude"}: "nan" was not in the range [-180, 80)
NoneType: None
{row: 6, column: "Longitude"}: "London & South East England" was not in the range [-180, 80)
NoneType: None
{row: 8, column: "ObservationDate"}: "2016-02-07T00:00" does not match the date format string "%Y-%m-%dT%H:%M:%S"
NoneType: None
Data validation failed. Please refer to the log file for detailed information.
Traceback (most recent call last):
  File "C:\Users\Michael\PycharmProjects\GFWeatherPipelineTask\weather_pipeline.py", line 25, in wrapped
    return f(*args, **kwargs)
  File "C:\Users\Michael\PycharmProjects\GFWeatherPipelineTask\weather_pipeline.py", line 204, in validate_weather_data
    "Data validation failed. Please refer to the log file for detailed information."
weather_pipeline.DataValidationError: Data validation failed. Please refer to the log file for detailed information.
[Errno 2] File  does not exist: ''
Traceback (most recent call last):
  File "C:\Users\Michael\PycharmProjects\GFWeatherPipelineTask\weather_pipeline.py", line 46, in import_monthly_weather_csv
    frame_out = pd.read_csv(f"{fpath}", na_values=-99).applymap(
  File "C:\Users\Michael\miniconda3\envs\GF Weather Pipeline Task\lib\site-packages\pandas\io\parsers.py", line 676, in parser_f
    return _read(filepath_or_buffer, kwds)
  File "C:\Users\Michael\miniconda3\envs\GF Weather Pipeline Task\lib\site-packages\pandas\io\parsers.py", line 448, in _read
    parser = TextFileReader(fp_or_buf, **kwds)
  File "C:\Users\Michael\miniconda3\envs\GF Weather Pipeline Task\lib\site-packages\pandas\io\parsers.py", line 880, in __init__
    self._make_engine(self.engine)
  File "C:\Users\Michael\miniconda3\envs\GF Weather Pipeline Task\lib\site-packages\pandas\io\parsers.py", line 1114, in _make_engine
    self._engine = CParserWrapper(self.f, **self.options)
  File "C:\Users\Michael\miniconda3\envs\GF Weather Pipeline Task\lib\site-packages\pandas\io\parsers.py", line 1891, in __init__
    self._reader = parsers.TextReader(src, **kwds)
  File "pandas\_libs\parsers.pyx", line 374, in pandas._libs.parsers.TextReader.__cinit__
  File "pandas\_libs\parsers.pyx", line 674, in pandas._libs.parsers.TextReader._setup_parser_source
FileNotFoundError: [Errno 2] File  does not exist: ''
No columns to parse from file
Traceback (most recent call last):
  File "C:\Users\Michael\PycharmProjects\GFWeatherPipelineTask\weather_pipeline.py", line 46, in import_monthly_weather_csv
    frame_out = pd.read_csv(f"{fpath}", na_values=-99).applymap(
  File "C:\Users\Michael\miniconda3\envs\GF Weather Pipeline Task\lib\site-packages\pandas\io\parsers.py", line 676, in parser_f
    return _read(filepath_or_buffer, kwds)
  File "C:\Users\Michael\miniconda3\envs\GF Weather Pipeline Task\lib\site-packages\pandas\io\parsers.py", line 448, in _read
    parser = TextFileReader(fp_or_buf, **kwds)
  File "C:\Users\Michael\miniconda3\envs\GF Weather Pipeline Task\lib\site-packages\pandas\io\parsers.py", line 880, in __init__
    self._make_engine(self.engine)
  File "C:\Users\Michael\miniconda3\envs\GF Weather Pipeline Task\lib\site-packages\pandas\io\parsers.py", line 1114, in _make_engine
    self._engine = CParserWrapper(self.f, **self.options)
  File "C:\Users\Michael\miniconda3\envs\GF Weather Pipeline Task\lib\site-packages\pandas\io\parsers.py", line 1891, in __init__
    self._reader = parsers.TextReader(src, **kwds)
  File "pandas\_libs\parsers.pyx", line 532, in pandas._libs.parsers.TextReader.__cinit__
pandas.errors.EmptyDataError: No columns to parse from file
The file only has a header and no data.
Traceback (most recent call last):
  File "C:\Users\Michael\PycharmProjects\GFWeatherPipelineTask\weather_pipeline.py", line 69, in import_monthly_weather_csv
    raise pd.errors.EmptyDataError("The file only has a header and no data.")
pandas.errors.EmptyDataError: The file only has a header and no data.
'utf-8' codec can't decode byte 0xa3 in position 0: invalid start byte
Traceback (most recent call last):
  File "C:\Users\Michael\PycharmProjects\GFWeatherPipelineTask\weather_pipeline.py", line 46, in import_monthly_weather_csv
    frame_out = pd.read_csv(f"{fpath}", na_values=-99).applymap(
  File "C:\Users\Michael\miniconda3\envs\GF Weather Pipeline Task\lib\site-packages\pandas\io\parsers.py", line 676, in parser_f
    return _read(filepath_or_buffer, kwds)
  File "C:\Users\Michael\miniconda3\envs\GF Weather Pipeline Task\lib\site-packages\pandas\io\parsers.py", line 448, in _read
    parser = TextFileReader(fp_or_buf, **kwds)
  File "C:\Users\Michael\miniconda3\envs\GF Weather Pipeline Task\lib\site-packages\pandas\io\parsers.py", line 880, in __init__
    self._make_engine(self.engine)
  File "C:\Users\Michael\miniconda3\envs\GF Weather Pipeline Task\lib\site-packages\pandas\io\parsers.py", line 1114, in _make_engine
    self._engine = CParserWrapper(self.f, **self.options)
  File "C:\Users\Michael\miniconda3\envs\GF Weather Pipeline Task\lib\site-packages\pandas\io\parsers.py", line 1891, in __init__
    self._reader = parsers.TextReader(src, **kwds)
  File "pandas\_libs\parsers.pyx", line 529, in pandas._libs.parsers.TextReader.__cinit__
  File "pandas\_libs\parsers.pyx", line 749, in pandas._libs.parsers.TextReader._get_header
UnicodeDecodeError: 'utf-8' codec can't decode byte 0xa3 in position 0: invalid start byte
Unexpected column names.
Traceback (most recent call last):
  File "C:\Users\Michael\PycharmProjects\GFWeatherPipelineTask\weather_pipeline.py", line 77, in import_monthly_weather_csv
    raise DataValidationError("Unexpected column names.")
weather_pipeline.DataValidationError: Unexpected column names.
Error tokenizing data. C error: Expected 15 fields in line 3, saw 16
Traceback (most recent call last):
  File "C:\Users\Michael\PycharmProjects\GFWeatherPipelineTask\weather_pipeline.py", line 46, in import_monthly_weather_csv
    frame_out = pd.read_csv(f"{fpath}", na_values=-99).applymap(
  File "C:\Users\Michael\miniconda3\envs\GF Weather Pipeline Task\lib\site-packages\pandas\io\parsers.py", line 676, in parser_f
    return _read(filepath_or_buffer, kwds)
  File "C:\Users\Michael\miniconda3\envs\GF Weather Pipeline Task\lib\site-packages\pandas\io\parsers.py", line 454, in _read
    data = parser.read(nrows)
  File "C:\Users\Michael\miniconda3\envs\GF Weather Pipeline Task\lib\site-packages\pandas\io\parsers.py", line 1133, in read
    ret = self._engine.read(nrows)
  File "C:\Users\Michael\miniconda3\envs\GF Weather Pipeline Task\lib\site-packages\pandas\io\parsers.py", line 2037, in read
    data = self._reader.read(nrows)
  File "pandas\_libs\parsers.pyx", line 860, in pandas._libs.parsers.TextReader.read
  File "pandas\_libs\parsers.pyx", line 875, in pandas._libs.parsers.TextReader._read_low_memory
  File "pandas\_libs\parsers.pyx", line 929, in pandas._libs.parsers.TextReader._read_rows
  File "pandas\_libs\parsers.pyx", line 916, in pandas._libs.parsers.TextReader._tokenize_rows
  File "pandas\_libs\parsers.pyx", line 2071, in pandas._libs.parsers.raise_parser_error
pandas.errors.ParserError: Error tokenizing data. C error: Expected 15 fields in line 3, saw 16

Missing column names or too few row data values.
Traceback (most recent call last):
  File "C:\Users\Michael\PycharmProjects\GFWeatherPipelineTask\weather_pipeline.py", line 72, in import_monthly_weather_csv
    "Missing column names or too few row data values."
weather_pipeline.DataValidationError: Missing column names or too few row data values.
Extra column names or too many row data values.
Traceback (most recent call last):
  File "C:\Users\Michael\PycharmProjects\GFWeatherPipelineTask\weather_pipeline.py", line 75, in import_monthly_weather_csv
    raise DataValidationError("Extra column names or too many row data values.")
weather_pipeline.DataValidationError: Extra column names or too many row data values.
The column ScreenTemperature has a dtype of object which is not a subclass of the required type float64
NoneType: None
The column Longitude has a dtype of object which is not a subclass of the required type float64
NoneType: None
{row: 3, column: "ForecastSiteCode"}: "6" was not in the range [1000, 100000)
NoneType: None
{row: 3, column: "ObservationDate"}: "nan" does not match the date format string "%Y-%m-%dT%H:%M:%S"
NoneType: None
{row: 3, column: "WindDirection"}: "40000" was not in the range [0, 17)
NoneType: None
{row: 3, column: "WindGust"}: "996.0" was not in the range [0, 255)
NoneType: None
{row: 3, column: "ScreenTemperature"}: "KIRKWALL (3017)" was not in the range [-50, 50)
NoneType: None
{row: 3, column: "Pressure"}: "58.95399999999999" was not in the range [870, 1085)
NoneType: None
{row: 3, column: "SignificantWeatherCode"}: "Orkney & Shetland" was not in the range [0, 31)
NoneType: None
{row: 3, column: "Latitude"}: "nan" was not in the range [-90, 90)
NoneType: None
{row: 3, column: "Longitude"}: "nan" was not in the range [-180, 80)
NoneType: None
{row: 6, column: "Longitude"}: "London & South East England" was not in the range [-180, 80)
NoneType: None
{row: 8, column: "ObservationDate"}: "2016-02-07T00:00" does not match the date format string "%Y-%m-%dT%H:%M:%S"
NoneType: None
Data validation failed. Please refer to the log file for detailed information.
Traceback (most recent call last):
  File "C:\Users\Michael\PycharmProjects\GFWeatherPipelineTask\weather_pipeline.py", line 25, in wrapped
    return f(*args, **kwargs)
  File "C:\Users\Michael\PycharmProjects\GFWeatherPipelineTask\weather_pipeline.py", line 204, in validate_weather_data
    "Data validation failed. Please refer to the log file for detailed information."
weather_pipeline.DataValidationError: Data validation failed. Please refer to the log file for detailed information.
[Errno 2] File  does not exist: ''
Traceback (most recent call last):
  File "C:\Users\Michael\PycharmProjects\GFWeatherPipelineTask\weather_pipeline.py", line 46, in import_monthly_weather_csv
    frame_out = pd.read_csv(f"{fpath}", na_values=-99).applymap(
  File "C:\Users\Michael\miniconda3\envs\GF Weather Pipeline Task\lib\site-packages\pandas\io\parsers.py", line 676, in parser_f
    return _read(filepath_or_buffer, kwds)
  File "C:\Users\Michael\miniconda3\envs\GF Weather Pipeline Task\lib\site-packages\pandas\io\parsers.py", line 448, in _read
    parser = TextFileReader(fp_or_buf, **kwds)
  File "C:\Users\Michael\miniconda3\envs\GF Weather Pipeline Task\lib\site-packages\pandas\io\parsers.py", line 880, in __init__
    self._make_engine(self.engine)
  File "C:\Users\Michael\miniconda3\envs\GF Weather Pipeline Task\lib\site-packages\pandas\io\parsers.py", line 1114, in _make_engine
    self._engine = CParserWrapper(self.f, **self.options)
  File "C:\Users\Michael\miniconda3\envs\GF Weather Pipeline Task\lib\site-packages\pandas\io\parsers.py", line 1891, in __init__
    self._reader = parsers.TextReader(src, **kwds)
  File "pandas\_libs\parsers.pyx", line 374, in pandas._libs.parsers.TextReader.__cinit__
  File "pandas\_libs\parsers.pyx", line 674, in pandas._libs.parsers.TextReader._setup_parser_source
FileNotFoundError: [Errno 2] File  does not exist: ''
No columns to parse from file
Traceback (most recent call last):
  File "C:\Users\Michael\PycharmProjects\GFWeatherPipelineTask\weather_pipeline.py", line 46, in import_monthly_weather_csv
    frame_out = pd.read_csv(f"{fpath}", na_values=-99).applymap(
  File "C:\Users\Michael\miniconda3\envs\GF Weather Pipeline Task\lib\site-packages\pandas\io\parsers.py", line 676, in parser_f
    return _read(filepath_or_buffer, kwds)
  File "C:\Users\Michael\miniconda3\envs\GF Weather Pipeline Task\lib\site-packages\pandas\io\parsers.py", line 448, in _read
    parser = TextFileReader(fp_or_buf, **kwds)
  File "C:\Users\Michael\miniconda3\envs\GF Weather Pipeline Task\lib\site-packages\pandas\io\parsers.py", line 880, in __init__
    self._make_engine(self.engine)
  File "C:\Users\Michael\miniconda3\envs\GF Weather Pipeline Task\lib\site-packages\pandas\io\parsers.py", line 1114, in _make_engine
    self._engine = CParserWrapper(self.f, **self.options)
  File "C:\Users\Michael\miniconda3\envs\GF Weather Pipeline Task\lib\site-packages\pandas\io\parsers.py", line 1891, in __init__
    self._reader = parsers.TextReader(src, **kwds)
  File "pandas\_libs\parsers.pyx", line 532, in pandas._libs.parsers.TextReader.__cinit__
pandas.errors.EmptyDataError: No columns to parse from file
The file only has a header and no data.
Traceback (most recent call last):
  File "C:\Users\Michael\PycharmProjects\GFWeatherPipelineTask\weather_pipeline.py", line 69, in import_monthly_weather_csv
    raise pd.errors.EmptyDataError("The file only has a header and no data.")
pandas.errors.EmptyDataError: The file only has a header and no data.
'utf-8' codec can't decode byte 0xa3 in position 0: invalid start byte
Traceback (most recent call last):
  File "C:\Users\Michael\PycharmProjects\GFWeatherPipelineTask\weather_pipeline.py", line 46, in import_monthly_weather_csv
    frame_out = pd.read_csv(f"{fpath}", na_values=-99).applymap(
  File "C:\Users\Michael\miniconda3\envs\GF Weather Pipeline Task\lib\site-packages\pandas\io\parsers.py", line 676, in parser_f
    return _read(filepath_or_buffer, kwds)
  File "C:\Users\Michael\miniconda3\envs\GF Weather Pipeline Task\lib\site-packages\pandas\io\parsers.py", line 448, in _read
    parser = TextFileReader(fp_or_buf, **kwds)
  File "C:\Users\Michael\miniconda3\envs\GF Weather Pipeline Task\lib\site-packages\pandas\io\parsers.py", line 880, in __init__
    self._make_engine(self.engine)
  File "C:\Users\Michael\miniconda3\envs\GF Weather Pipeline Task\lib\site-packages\pandas\io\parsers.py", line 1114, in _make_engine
    self._engine = CParserWrapper(self.f, **self.options)
  File "C:\Users\Michael\miniconda3\envs\GF Weather Pipeline Task\lib\site-packages\pandas\io\parsers.py", line 1891, in __init__
    self._reader = parsers.TextReader(src, **kwds)
  File "pandas\_libs\parsers.pyx", line 529, in pandas._libs.parsers.TextReader.__cinit__
  File "pandas\_libs\parsers.pyx", line 749, in pandas._libs.parsers.TextReader._get_header
UnicodeDecodeError: 'utf-8' codec can't decode byte 0xa3 in position 0: invalid start byte
Unexpected column names.
Traceback (most recent call last):
  File "C:\Users\Michael\PycharmProjects\GFWeatherPipelineTask\weather_pipeline.py", line 77, in import_monthly_weather_csv
    raise DataValidationError("Unexpected column names.")
weather_pipeline.DataValidationError: Unexpected column names.
Error tokenizing data. C error: Expected 15 fields in line 3, saw 16
Traceback (most recent call last):
  File "C:\Users\Michael\PycharmProjects\GFWeatherPipelineTask\weather_pipeline.py", line 46, in import_monthly_weather_csv
    frame_out = pd.read_csv(f"{fpath}", na_values=-99).applymap(
  File "C:\Users\Michael\miniconda3\envs\GF Weather Pipeline Task\lib\site-packages\pandas\io\parsers.py", line 676, in parser_f
    return _read(filepath_or_buffer, kwds)
  File "C:\Users\Michael\miniconda3\envs\GF Weather Pipeline Task\lib\site-packages\pandas\io\parsers.py", line 454, in _read
    data = parser.read(nrows)
  File "C:\Users\Michael\miniconda3\envs\GF Weather Pipeline Task\lib\site-packages\pandas\io\parsers.py", line 1133, in read
    ret = self._engine.read(nrows)
  File "C:\Users\Michael\miniconda3\envs\GF Weather Pipeline Task\lib\site-packages\pandas\io\parsers.py", line 2037, in read
    data = self._reader.read(nrows)
  File "pandas\_libs\parsers.pyx", line 860, in pandas._libs.parsers.TextReader.read
  File "pandas\_libs\parsers.pyx", line 875, in pandas._libs.parsers.TextReader._read_low_memory
  File "pandas\_libs\parsers.pyx", line 929, in pandas._libs.parsers.TextReader._read_rows
  File "pandas\_libs\parsers.pyx", line 916, in pandas._libs.parsers.TextReader._tokenize_rows
  File "pandas\_libs\parsers.pyx", line 2071, in pandas._libs.parsers.raise_parser_error
pandas.errors.ParserError: Error tokenizing data. C error: Expected 15 fields in line 3, saw 16

Missing column names or too few row data values.
Traceback (most recent call last):
  File "C:\Users\Michael\PycharmProjects\GFWeatherPipelineTask\weather_pipeline.py", line 72, in import_monthly_weather_csv
    "Missing column names or too few row data values."
weather_pipeline.DataValidationError: Missing column names or too few row data values.
Extra column names or too many row data values.
Traceback (most recent call last):
  File "C:\Users\Michael\PycharmProjects\GFWeatherPipelineTask\weather_pipeline.py", line 75, in import_monthly_weather_csv
    raise DataValidationError("Extra column names or too many row data values.")
weather_pipeline.DataValidationError: Extra column names or too many row data values.
The column ScreenTemperature has a dtype of object which is not a subclass of the required type float64
NoneType: None
The column Longitude has a dtype of object which is not a subclass of the required type float64
NoneType: None
{row: 3, column: "ForecastSiteCode"}: "6" was not in the range [1000, 100000)
NoneType: None
{row: 3, column: "ObservationDate"}: "nan" does not match the date format string "%Y-%m-%dT%H:%M:%S"
NoneType: None
{row: 3, column: "WindDirection"}: "40000" was not in the range [0, 17)
NoneType: None
{row: 3, column: "WindGust"}: "996.0" was not in the range [0, 255)
NoneType: None
{row: 3, column: "ScreenTemperature"}: "KIRKWALL (3017)" was not in the range [-50, 50)
NoneType: None
{row: 3, column: "Pressure"}: "58.95399999999999" was not in the range [870, 1085)
NoneType: None
{row: 3, column: "SignificantWeatherCode"}: "Orkney & Shetland" was not in the range [0, 31)
NoneType: None
{row: 3, column: "Latitude"}: "nan" was not in the range [-90, 90)
NoneType: None
{row: 3, column: "Longitude"}: "nan" was not in the range [-180, 80)
NoneType: None
{row: 6, column: "Longitude"}: "London & South East England" was not in the range [-180, 80)
NoneType: None
{row: 8, column: "ObservationDate"}: "2016-02-07T00:00" does not match the date format string "%Y-%m-%dT%H:%M:%S"
NoneType: None
Data validation failed. Please refer to the log file for detailed information.
Traceback (most recent call last):
  File "C:\Users\Michael\PycharmProjects\GFWeatherPipelineTask\weather_pipeline.py", line 25, in wrapped
    return f(*args, **kwargs)
  File "C:\Users\Michael\PycharmProjects\GFWeatherPipelineTask\weather_pipeline.py", line 204, in validate_weather_data
    "Data validation failed. Please refer to the log file for detailed information."
weather_pipeline.DataValidationError: Data validation failed. Please refer to the log file for detailed information.
[Errno 2] File  does not exist: ''
Traceback (most recent call last):
  File "C:\Users\Michael\PycharmProjects\GFWeatherPipelineTask\weather_pipeline.py", line 46, in import_monthly_weather_csv
    frame_out = pd.read_csv(f"{fpath}", na_values=-99).applymap(
  File "C:\Users\Michael\miniconda3\envs\GF Weather Pipeline Task\lib\site-packages\pandas\io\parsers.py", line 676, in parser_f
    return _read(filepath_or_buffer, kwds)
  File "C:\Users\Michael\miniconda3\envs\GF Weather Pipeline Task\lib\site-packages\pandas\io\parsers.py", line 448, in _read
    parser = TextFileReader(fp_or_buf, **kwds)
  File "C:\Users\Michael\miniconda3\envs\GF Weather Pipeline Task\lib\site-packages\pandas\io\parsers.py", line 880, in __init__
    self._make_engine(self.engine)
  File "C:\Users\Michael\miniconda3\envs\GF Weather Pipeline Task\lib\site-packages\pandas\io\parsers.py", line 1114, in _make_engine
    self._engine = CParserWrapper(self.f, **self.options)
  File "C:\Users\Michael\miniconda3\envs\GF Weather Pipeline Task\lib\site-packages\pandas\io\parsers.py", line 1891, in __init__
    self._reader = parsers.TextReader(src, **kwds)
  File "pandas\_libs\parsers.pyx", line 374, in pandas._libs.parsers.TextReader.__cinit__
  File "pandas\_libs\parsers.pyx", line 674, in pandas._libs.parsers.TextReader._setup_parser_source
FileNotFoundError: [Errno 2] File  does not exist: ''
No columns to parse from file
Traceback (most recent call last):
  File "C:\Users\Michael\PycharmProjects\GFWeatherPipelineTask\weather_pipeline.py", line 46, in import_monthly_weather_csv
    frame_out = pd.read_csv(f"{fpath}", na_values=-99).applymap(
  File "C:\Users\Michael\miniconda3\envs\GF Weather Pipeline Task\lib\site-packages\pandas\io\parsers.py", line 676, in parser_f
    return _read(filepath_or_buffer, kwds)
  File "C:\Users\Michael\miniconda3\envs\GF Weather Pipeline Task\lib\site-packages\pandas\io\parsers.py", line 448, in _read
    parser = TextFileReader(fp_or_buf, **kwds)
  File "C:\Users\Michael\miniconda3\envs\GF Weather Pipeline Task\lib\site-packages\pandas\io\parsers.py", line 880, in __init__
    self._make_engine(self.engine)
  File "C:\Users\Michael\miniconda3\envs\GF Weather Pipeline Task\lib\site-packages\pandas\io\parsers.py", line 1114, in _make_engine
    self._engine = CParserWrapper(self.f, **self.options)
  File "C:\Users\Michael\miniconda3\envs\GF Weather Pipeline Task\lib\site-packages\pandas\io\parsers.py", line 1891, in __init__
    self._reader = parsers.TextReader(src, **kwds)
  File "pandas\_libs\parsers.pyx", line 532, in pandas._libs.parsers.TextReader.__cinit__
pandas.errors.EmptyDataError: No columns to parse from file
The file only has a header and no data.
Traceback (most recent call last):
  File "C:\Users\Michael\PycharmProjects\GFWeatherPipelineTask\weather_pipeline.py", line 69, in import_monthly_weather_csv
    raise pd.errors.EmptyDataError("The file only has a header and no data.")
pandas.errors.EmptyDataError: The file only has a header and no data.
'utf-8' codec can't decode byte 0xa3 in position 0: invalid start byte
Traceback (most recent call last):
  File "C:\Users\Michael\PycharmProjects\GFWeatherPipelineTask\weather_pipeline.py", line 46, in import_monthly_weather_csv
    frame_out = pd.read_csv(f"{fpath}", na_values=-99).applymap(
  File "C:\Users\Michael\miniconda3\envs\GF Weather Pipeline Task\lib\site-packages\pandas\io\parsers.py", line 676, in parser_f
    return _read(filepath_or_buffer, kwds)
  File "C:\Users\Michael\miniconda3\envs\GF Weather Pipeline Task\lib\site-packages\pandas\io\parsers.py", line 448, in _read
    parser = TextFileReader(fp_or_buf, **kwds)
  File "C:\Users\Michael\miniconda3\envs\GF Weather Pipeline Task\lib\site-packages\pandas\io\parsers.py", line 880, in __init__
    self._make_engine(self.engine)
  File "C:\Users\Michael\miniconda3\envs\GF Weather Pipeline Task\lib\site-packages\pandas\io\parsers.py", line 1114, in _make_engine
    self._engine = CParserWrapper(self.f, **self.options)
  File "C:\Users\Michael\miniconda3\envs\GF Weather Pipeline Task\lib\site-packages\pandas\io\parsers.py", line 1891, in __init__
    self._reader = parsers.TextReader(src, **kwds)
  File "pandas\_libs\parsers.pyx", line 529, in pandas._libs.parsers.TextReader.__cinit__
  File "pandas\_libs\parsers.pyx", line 749, in pandas._libs.parsers.TextReader._get_header
UnicodeDecodeError: 'utf-8' codec can't decode byte 0xa3 in position 0: invalid start byte
Unexpected column names.
Traceback (most recent call last):
  File "C:\Users\Michael\PycharmProjects\GFWeatherPipelineTask\weather_pipeline.py", line 77, in import_monthly_weather_csv
    raise DataValidationError("Unexpected column names.")
weather_pipeline.DataValidationError: Unexpected column names.
Error tokenizing data. C error: Expected 15 fields in line 3, saw 16
Traceback (most recent call last):
  File "C:\Users\Michael\PycharmProjects\GFWeatherPipelineTask\weather_pipeline.py", line 46, in import_monthly_weather_csv
    frame_out = pd.read_csv(f"{fpath}", na_values=-99).applymap(
  File "C:\Users\Michael\miniconda3\envs\GF Weather Pipeline Task\lib\site-packages\pandas\io\parsers.py", line 676, in parser_f
    return _read(filepath_or_buffer, kwds)
  File "C:\Users\Michael\miniconda3\envs\GF Weather Pipeline Task\lib\site-packages\pandas\io\parsers.py", line 454, in _read
    data = parser.read(nrows)
  File "C:\Users\Michael\miniconda3\envs\GF Weather Pipeline Task\lib\site-packages\pandas\io\parsers.py", line 1133, in read
    ret = self._engine.read(nrows)
  File "C:\Users\Michael\miniconda3\envs\GF Weather Pipeline Task\lib\site-packages\pandas\io\parsers.py", line 2037, in read
    data = self._reader.read(nrows)
  File "pandas\_libs\parsers.pyx", line 860, in pandas._libs.parsers.TextReader.read
  File "pandas\_libs\parsers.pyx", line 875, in pandas._libs.parsers.TextReader._read_low_memory
  File "pandas\_libs\parsers.pyx", line 929, in pandas._libs.parsers.TextReader._read_rows
  File "pandas\_libs\parsers.pyx", line 916, in pandas._libs.parsers.TextReader._tokenize_rows
  File "pandas\_libs\parsers.pyx", line 2071, in pandas._libs.parsers.raise_parser_error
pandas.errors.ParserError: Error tokenizing data. C error: Expected 15 fields in line 3, saw 16

Missing column names or too few row data values.
Traceback (most recent call last):
  File "C:\Users\Michael\PycharmProjects\GFWeatherPipelineTask\weather_pipeline.py", line 72, in import_monthly_weather_csv
    "Missing column names or too few row data values."
weather_pipeline.DataValidationError: Missing column names or too few row data values.
Extra column names or too many row data values.
Traceback (most recent call last):
  File "C:\Users\Michael\PycharmProjects\GFWeatherPipelineTask\weather_pipeline.py", line 75, in import_monthly_weather_csv
    raise DataValidationError("Extra column names or too many row data values.")
weather_pipeline.DataValidationError: Extra column names or too many row data values.
The column ScreenTemperature has a dtype of object which is not a subclass of the required type float64
NoneType: None
The column Longitude has a dtype of object which is not a subclass of the required type float64
NoneType: None
{row: 3, column: "ForecastSiteCode"}: "6" was not in the range [1000, 100000)
NoneType: None
{row: 3, column: "ObservationDate"}: "nan" does not match the date format string "%Y-%m-%dT%H:%M:%S"
NoneType: None
{row: 3, column: "WindDirection"}: "40000" was not in the range [0, 17)
NoneType: None
{row: 3, column: "WindGust"}: "996.0" was not in the range [0, 255)
NoneType: None
{row: 3, column: "ScreenTemperature"}: "KIRKWALL (3017)" was not in the range [-50, 50)
NoneType: None
{row: 3, column: "Pressure"}: "58.95399999999999" was not in the range [870, 1085)
NoneType: None
{row: 3, column: "SignificantWeatherCode"}: "Orkney & Shetland" was not in the range [0, 31)
NoneType: None
{row: 3, column: "Latitude"}: "nan" was not in the range [-90, 90)
NoneType: None
{row: 3, column: "Longitude"}: "nan" was not in the range [-180, 80)
NoneType: None
{row: 6, column: "Longitude"}: "London & South East England" was not in the range [-180, 80)
NoneType: None
{row: 8, column: "ObservationDate"}: "2016-02-07T00:00" does not match the date format string "%Y-%m-%dT%H:%M:%S"
NoneType: None
Data validation failed. Please refer to the log file for detailed information.
Traceback (most recent call last):
  File "C:\Users\Michael\PycharmProjects\GFWeatherPipelineTask\weather_pipeline.py", line 25, in wrapped
    return f(*args, **kwargs)
  File "C:\Users\Michael\PycharmProjects\GFWeatherPipelineTask\weather_pipeline.py", line 204, in validate_weather_data
    "Data validation failed. Please refer to the log file for detailed information."
weather_pipeline.DataValidationError: Data validation failed. Please refer to the log file for detailed information.
TransportError(500, '{\r\n  "errorMessage" : "VALIDATION ERROR: From line 8, column 17 to line 8, column 19: Object \'C:/Users/Michael/PycharmProjects/GFWeatherPipelineTask/Data/wether.parquet\' not found within \'dfs\'\\n\\n\\r\\n[Error Id: 022e0435-4671-494a-b101-c8a0e6173681 ]"\r\n}')
Traceback (most recent call last):
  File "C:\Users\Michael\PycharmProjects\GFWeatherPipelineTask\weather_pipeline.py", line 25, in wrapped
    return f(*args, **kwargs)
  File "C:\Users\Michael\PycharmProjects\GFWeatherPipelineTask\weather_pipeline.py", line 354, in query_parquet
    return drill.query(sql, timeout=10)
  File "C:\Users\Michael\miniconda3\envs\GF Weather Pipeline Task\lib\site-packages\pydrill\client\__init__.py", line 62, in query
    'request_timeout': timeout
  File "C:\Users\Michael\miniconda3\envs\GF Weather Pipeline Task\lib\site-packages\pydrill\client\__init__.py", line 24, in perform_request
    return self.transport.perform_request(method, url, params, body)
  File "C:\Users\Michael\miniconda3\envs\GF Weather Pipeline Task\lib\site-packages\pydrill\transport.py", line 79, in perform_request
    timeout=timeout)
  File "C:\Users\Michael\miniconda3\envs\GF Weather Pipeline Task\lib\site-packages\pydrill\connection\requests_conn.py", line 105, in perform_request
    self._raise_error(response.status_code, raw_data)
  File "C:\Users\Michael\miniconda3\envs\GF Weather Pipeline Task\lib\site-packages\pydrill\connection\base.py", line 113, in _raise_error
    raise HTTP_EXCEPTIONS.get(status_code, TransportError)(status_code, error_message, additional_info)
pydrill.exceptions.TransportError: TransportError(500, '{\r\n  "errorMessage" : "VALIDATION ERROR: From line 8, column 17 to line 8, column 19: Object \'C:/Users/Michael/PycharmProjects/GFWeatherPipelineTask/Data/wether.parquet\' not found within \'dfs\'\\n\\n\\r\\n[Error Id: 022e0435-4671-494a-b101-c8a0e6173681 ]"\r\n}')
TransportError(500, '{\r\n  "errorMessage" : "VALIDATION ERROR: From line 8, column 17 to line 8, column 19: Object \'C:/Users/Michael/PycharmProjects/GFWeatherPipelineTask/Data/wether.parquet\' not found within \'dfs\'\\n\\n\\r\\n[Error Id: 022e0435-4671-494a-b101-c8a0e6173681 ]"\r\n}')
Traceback (most recent call last):
  File "C:\Users\Michael\PycharmProjects\GFWeatherPipelineTask\weather_pipeline.py", line 25, in wrapped
    return f(*args, **kwargs)
  File "C:\Users\Michael\PycharmProjects\GFWeatherPipelineTask\weather_pipeline.py", line 336, in max_daily_average_temperature
    query_out = query_parquet(sql)
  File "C:\Users\Michael\PycharmProjects\GFWeatherPipelineTask\weather_pipeline.py", line 25, in wrapped
    return f(*args, **kwargs)
  File "C:\Users\Michael\PycharmProjects\GFWeatherPipelineTask\weather_pipeline.py", line 354, in query_parquet
    return drill.query(sql, timeout=10)
  File "C:\Users\Michael\miniconda3\envs\GF Weather Pipeline Task\lib\site-packages\pydrill\client\__init__.py", line 62, in query
    'request_timeout': timeout
  File "C:\Users\Michael\miniconda3\envs\GF Weather Pipeline Task\lib\site-packages\pydrill\client\__init__.py", line 24, in perform_request
    return self.transport.perform_request(method, url, params, body)
  File "C:\Users\Michael\miniconda3\envs\GF Weather Pipeline Task\lib\site-packages\pydrill\transport.py", line 79, in perform_request
    timeout=timeout)
  File "C:\Users\Michael\miniconda3\envs\GF Weather Pipeline Task\lib\site-packages\pydrill\connection\requests_conn.py", line 105, in perform_request
    self._raise_error(response.status_code, raw_data)
  File "C:\Users\Michael\miniconda3\envs\GF Weather Pipeline Task\lib\site-packages\pydrill\connection\base.py", line 113, in _raise_error
    raise HTTP_EXCEPTIONS.get(status_code, TransportError)(status_code, error_message, additional_info)
pydrill.exceptions.TransportError: TransportError(500, '{\r\n  "errorMessage" : "VALIDATION ERROR: From line 8, column 17 to line 8, column 19: Object \'C:/Users/Michael/PycharmProjects/GFWeatherPipelineTask/Data/wether.parquet\' not found within \'dfs\'\\n\\n\\r\\n[Error Id: 022e0435-4671-494a-b101-c8a0e6173681 ]"\r\n}')
TransportError(500, '{\r\n  "errorMessage" : "VALIDATION ERROR: From line 2, column 17 to line 2, column 30: Expression \'ObservatinDate\' is not being grouped\\n\\n\\r\\n[Error Id: 7266af6a-a216-45e5-8ffd-c495e930ae72 ]"\r\n}')
Traceback (most recent call last):
  File "C:\Users\Michael\PycharmProjects\GFWeatherPipelineTask\weather_pipeline.py", line 25, in wrapped
    return f(*args, **kwargs)
  File "C:\Users\Michael\PycharmProjects\GFWeatherPipelineTask\weather_pipeline.py", line 354, in query_parquet
    return drill.query(sql, timeout=10)
  File "C:\Users\Michael\miniconda3\envs\GF Weather Pipeline Task\lib\site-packages\pydrill\client\__init__.py", line 62, in query
    'request_timeout': timeout
  File "C:\Users\Michael\miniconda3\envs\GF Weather Pipeline Task\lib\site-packages\pydrill\client\__init__.py", line 24, in perform_request
    return self.transport.perform_request(method, url, params, body)
  File "C:\Users\Michael\miniconda3\envs\GF Weather Pipeline Task\lib\site-packages\pydrill\transport.py", line 79, in perform_request
    timeout=timeout)
  File "C:\Users\Michael\miniconda3\envs\GF Weather Pipeline Task\lib\site-packages\pydrill\connection\requests_conn.py", line 105, in perform_request
    self._raise_error(response.status_code, raw_data)
  File "C:\Users\Michael\miniconda3\envs\GF Weather Pipeline Task\lib\site-packages\pydrill\connection\base.py", line 113, in _raise_error
    raise HTTP_EXCEPTIONS.get(status_code, TransportError)(status_code, error_message, additional_info)
pydrill.exceptions.TransportError: TransportError(500, '{\r\n  "errorMessage" : "VALIDATION ERROR: From line 2, column 17 to line 2, column 30: Expression \'ObservatinDate\' is not being grouped\\n\\n\\r\\n[Error Id: 7266af6a-a216-45e5-8ffd-c495e930ae72 ]"\r\n}')
[Errno 2] File  does not exist: ''
Traceback (most recent call last):
  File "C:\Users\Michael\PycharmProjects\GFWeatherPipelineTask\weather_pipeline.py", line 46, in import_monthly_weather_csv
    frame_out = pd.read_csv(f"{fpath}", na_values=-99).applymap(
  File "C:\Users\Michael\miniconda3\envs\GF Weather Pipeline Task\lib\site-packages\pandas\io\parsers.py", line 676, in parser_f
    return _read(filepath_or_buffer, kwds)
  File "C:\Users\Michael\miniconda3\envs\GF Weather Pipeline Task\lib\site-packages\pandas\io\parsers.py", line 448, in _read
    parser = TextFileReader(fp_or_buf, **kwds)
  File "C:\Users\Michael\miniconda3\envs\GF Weather Pipeline Task\lib\site-packages\pandas\io\parsers.py", line 880, in __init__
    self._make_engine(self.engine)
  File "C:\Users\Michael\miniconda3\envs\GF Weather Pipeline Task\lib\site-packages\pandas\io\parsers.py", line 1114, in _make_engine
    self._engine = CParserWrapper(self.f, **self.options)
  File "C:\Users\Michael\miniconda3\envs\GF Weather Pipeline Task\lib\site-packages\pandas\io\parsers.py", line 1891, in __init__
    self._reader = parsers.TextReader(src, **kwds)
  File "pandas\_libs\parsers.pyx", line 374, in pandas._libs.parsers.TextReader.__cinit__
  File "pandas\_libs\parsers.pyx", line 674, in pandas._libs.parsers.TextReader._setup_parser_source
FileNotFoundError: [Errno 2] File  does not exist: ''
No columns to parse from file
Traceback (most recent call last):
  File "C:\Users\Michael\PycharmProjects\GFWeatherPipelineTask\weather_pipeline.py", line 46, in import_monthly_weather_csv
    frame_out = pd.read_csv(f"{fpath}", na_values=-99).applymap(
  File "C:\Users\Michael\miniconda3\envs\GF Weather Pipeline Task\lib\site-packages\pandas\io\parsers.py", line 676, in parser_f
    return _read(filepath_or_buffer, kwds)
  File "C:\Users\Michael\miniconda3\envs\GF Weather Pipeline Task\lib\site-packages\pandas\io\parsers.py", line 448, in _read
    parser = TextFileReader(fp_or_buf, **kwds)
  File "C:\Users\Michael\miniconda3\envs\GF Weather Pipeline Task\lib\site-packages\pandas\io\parsers.py", line 880, in __init__
    self._make_engine(self.engine)
  File "C:\Users\Michael\miniconda3\envs\GF Weather Pipeline Task\lib\site-packages\pandas\io\parsers.py", line 1114, in _make_engine
    self._engine = CParserWrapper(self.f, **self.options)
  File "C:\Users\Michael\miniconda3\envs\GF Weather Pipeline Task\lib\site-packages\pandas\io\parsers.py", line 1891, in __init__
    self._reader = parsers.TextReader(src, **kwds)
  File "pandas\_libs\parsers.pyx", line 532, in pandas._libs.parsers.TextReader.__cinit__
pandas.errors.EmptyDataError: No columns to parse from file
The file only has a header and no data.
Traceback (most recent call last):
  File "C:\Users\Michael\PycharmProjects\GFWeatherPipelineTask\weather_pipeline.py", line 69, in import_monthly_weather_csv
    raise pd.errors.EmptyDataError("The file only has a header and no data.")
pandas.errors.EmptyDataError: The file only has a header and no data.
'utf-8' codec can't decode byte 0xa3 in position 0: invalid start byte
Traceback (most recent call last):
  File "C:\Users\Michael\PycharmProjects\GFWeatherPipelineTask\weather_pipeline.py", line 46, in import_monthly_weather_csv
    frame_out = pd.read_csv(f"{fpath}", na_values=-99).applymap(
  File "C:\Users\Michael\miniconda3\envs\GF Weather Pipeline Task\lib\site-packages\pandas\io\parsers.py", line 676, in parser_f
    return _read(filepath_or_buffer, kwds)
  File "C:\Users\Michael\miniconda3\envs\GF Weather Pipeline Task\lib\site-packages\pandas\io\parsers.py", line 448, in _read
    parser = TextFileReader(fp_or_buf, **kwds)
  File "C:\Users\Michael\miniconda3\envs\GF Weather Pipeline Task\lib\site-packages\pandas\io\parsers.py", line 880, in __init__
    self._make_engine(self.engine)
  File "C:\Users\Michael\miniconda3\envs\GF Weather Pipeline Task\lib\site-packages\pandas\io\parsers.py", line 1114, in _make_engine
    self._engine = CParserWrapper(self.f, **self.options)
  File "C:\Users\Michael\miniconda3\envs\GF Weather Pipeline Task\lib\site-packages\pandas\io\parsers.py", line 1891, in __init__
    self._reader = parsers.TextReader(src, **kwds)
  File "pandas\_libs\parsers.pyx", line 529, in pandas._libs.parsers.TextReader.__cinit__
  File "pandas\_libs\parsers.pyx", line 749, in pandas._libs.parsers.TextReader._get_header
UnicodeDecodeError: 'utf-8' codec can't decode byte 0xa3 in position 0: invalid start byte
Unexpected column names.
Traceback (most recent call last):
  File "C:\Users\Michael\PycharmProjects\GFWeatherPipelineTask\weather_pipeline.py", line 77, in import_monthly_weather_csv
    raise DataValidationError("Unexpected column names.")
weather_pipeline.DataValidationError: Unexpected column names.
Error tokenizing data. C error: Expected 15 fields in line 3, saw 16
Traceback (most recent call last):
  File "C:\Users\Michael\PycharmProjects\GFWeatherPipelineTask\weather_pipeline.py", line 46, in import_monthly_weather_csv
    frame_out = pd.read_csv(f"{fpath}", na_values=-99).applymap(
  File "C:\Users\Michael\miniconda3\envs\GF Weather Pipeline Task\lib\site-packages\pandas\io\parsers.py", line 676, in parser_f
    return _read(filepath_or_buffer, kwds)
  File "C:\Users\Michael\miniconda3\envs\GF Weather Pipeline Task\lib\site-packages\pandas\io\parsers.py", line 454, in _read
    data = parser.read(nrows)
  File "C:\Users\Michael\miniconda3\envs\GF Weather Pipeline Task\lib\site-packages\pandas\io\parsers.py", line 1133, in read
    ret = self._engine.read(nrows)
  File "C:\Users\Michael\miniconda3\envs\GF Weather Pipeline Task\lib\site-packages\pandas\io\parsers.py", line 2037, in read
    data = self._reader.read(nrows)
  File "pandas\_libs\parsers.pyx", line 860, in pandas._libs.parsers.TextReader.read
  File "pandas\_libs\parsers.pyx", line 875, in pandas._libs.parsers.TextReader._read_low_memory
  File "pandas\_libs\parsers.pyx", line 929, in pandas._libs.parsers.TextReader._read_rows
  File "pandas\_libs\parsers.pyx", line 916, in pandas._libs.parsers.TextReader._tokenize_rows
  File "pandas\_libs\parsers.pyx", line 2071, in pandas._libs.parsers.raise_parser_error
pandas.errors.ParserError: Error tokenizing data. C error: Expected 15 fields in line 3, saw 16

Missing column names or too few row data values.
Traceback (most recent call last):
  File "C:\Users\Michael\PycharmProjects\GFWeatherPipelineTask\weather_pipeline.py", line 72, in import_monthly_weather_csv
    "Missing column names or too few row data values."
weather_pipeline.DataValidationError: Missing column names or too few row data values.
Extra column names or too many row data values.
Traceback (most recent call last):
  File "C:\Users\Michael\PycharmProjects\GFWeatherPipelineTask\weather_pipeline.py", line 75, in import_monthly_weather_csv
    raise DataValidationError("Extra column names or too many row data values.")
weather_pipeline.DataValidationError: Extra column names or too many row data values.
The column ScreenTemperature has a dtype of object which is not a subclass of the required type float64
NoneType: None
The column Longitude has a dtype of object which is not a subclass of the required type float64
NoneType: None
{row: 3, column: "ForecastSiteCode"}: "6" was not in the range [1000, 100000)
NoneType: None
{row: 3, column: "ObservationDate"}: "nan" does not match the date format string "%Y-%m-%dT%H:%M:%S"
NoneType: None
{row: 3, column: "WindDirection"}: "40000" was not in the range [0, 17)
NoneType: None
{row: 3, column: "WindGust"}: "996.0" was not in the range [0, 255)
NoneType: None
{row: 3, column: "ScreenTemperature"}: "KIRKWALL (3017)" was not in the range [-50, 50)
NoneType: None
{row: 3, column: "Pressure"}: "58.95399999999999" was not in the range [870, 1085)
NoneType: None
{row: 3, column: "SignificantWeatherCode"}: "Orkney & Shetland" was not in the range [0, 31)
NoneType: None
{row: 3, column: "Latitude"}: "nan" was not in the range [-90, 90)
NoneType: None
{row: 3, column: "Longitude"}: "nan" was not in the range [-180, 80)
NoneType: None
{row: 6, column: "Longitude"}: "London & South East England" was not in the range [-180, 80)
NoneType: None
{row: 8, column: "ObservationDate"}: "2016-02-07T00:00" does not match the date format string "%Y-%m-%dT%H:%M:%S"
NoneType: None
Data validation failed. Please refer to the log file for detailed information.
Traceback (most recent call last):
  File "C:\Users\Michael\PycharmProjects\GFWeatherPipelineTask\weather_pipeline.py", line 25, in wrapped
    return f(*args, **kwargs)
  File "C:\Users\Michael\PycharmProjects\GFWeatherPipelineTask\weather_pipeline.py", line 204, in validate_weather_data
    "Data validation failed. Please refer to the log file for detailed information."
weather_pipeline.DataValidationError: Data validation failed. Please refer to the log file for detailed information.
TransportError(500, '{\r\n  "errorMessage" : "VALIDATION ERROR: From line 8, column 17 to line 8, column 19: Object \'C:/Users/Michael/PycharmProjects/GFWeatherPipelineTask/Data/wether.parquet\' not found within \'dfs\'\\n\\n\\r\\n[Error Id: 84c0f2b3-e07d-4518-99e8-8b9fbadda518 ]"\r\n}')
Traceback (most recent call last):
  File "C:\Users\Michael\PycharmProjects\GFWeatherPipelineTask\weather_pipeline.py", line 25, in wrapped
    return f(*args, **kwargs)
  File "C:\Users\Michael\PycharmProjects\GFWeatherPipelineTask\weather_pipeline.py", line 354, in query_parquet
    return drill.query(sql, timeout=10)
  File "C:\Users\Michael\miniconda3\envs\GF Weather Pipeline Task\lib\site-packages\pydrill\client\__init__.py", line 62, in query
    'request_timeout': timeout
  File "C:\Users\Michael\miniconda3\envs\GF Weather Pipeline Task\lib\site-packages\pydrill\client\__init__.py", line 24, in perform_request
    return self.transport.perform_request(method, url, params, body)
  File "C:\Users\Michael\miniconda3\envs\GF Weather Pipeline Task\lib\site-packages\pydrill\transport.py", line 79, in perform_request
    timeout=timeout)
  File "C:\Users\Michael\miniconda3\envs\GF Weather Pipeline Task\lib\site-packages\pydrill\connection\requests_conn.py", line 105, in perform_request
    self._raise_error(response.status_code, raw_data)
  File "C:\Users\Michael\miniconda3\envs\GF Weather Pipeline Task\lib\site-packages\pydrill\connection\base.py", line 113, in _raise_error
    raise HTTP_EXCEPTIONS.get(status_code, TransportError)(status_code, error_message, additional_info)
pydrill.exceptions.TransportError: TransportError(500, '{\r\n  "errorMessage" : "VALIDATION ERROR: From line 8, column 17 to line 8, column 19: Object \'C:/Users/Michael/PycharmProjects/GFWeatherPipelineTask/Data/wether.parquet\' not found within \'dfs\'\\n\\n\\r\\n[Error Id: 84c0f2b3-e07d-4518-99e8-8b9fbadda518 ]"\r\n}')
TransportError(500, '{\r\n  "errorMessage" : "VALIDATION ERROR: From line 8, column 17 to line 8, column 19: Object \'C:/Users/Michael/PycharmProjects/GFWeatherPipelineTask/Data/wether.parquet\' not found within \'dfs\'\\n\\n\\r\\n[Error Id: 84c0f2b3-e07d-4518-99e8-8b9fbadda518 ]"\r\n}')
Traceback (most recent call last):
  File "C:\Users\Michael\PycharmProjects\GFWeatherPipelineTask\weather_pipeline.py", line 25, in wrapped
    return f(*args, **kwargs)
  File "C:\Users\Michael\PycharmProjects\GFWeatherPipelineTask\weather_pipeline.py", line 336, in max_daily_average_temperature
    query_out = query_parquet(sql)
  File "C:\Users\Michael\PycharmProjects\GFWeatherPipelineTask\weather_pipeline.py", line 25, in wrapped
    return f(*args, **kwargs)
  File "C:\Users\Michael\PycharmProjects\GFWeatherPipelineTask\weather_pipeline.py", line 354, in query_parquet
    return drill.query(sql, timeout=10)
  File "C:\Users\Michael\miniconda3\envs\GF Weather Pipeline Task\lib\site-packages\pydrill\client\__init__.py", line 62, in query
    'request_timeout': timeout
  File "C:\Users\Michael\miniconda3\envs\GF Weather Pipeline Task\lib\site-packages\pydrill\client\__init__.py", line 24, in perform_request
    return self.transport.perform_request(method, url, params, body)
  File "C:\Users\Michael\miniconda3\envs\GF Weather Pipeline Task\lib\site-packages\pydrill\transport.py", line 79, in perform_request
    timeout=timeout)
  File "C:\Users\Michael\miniconda3\envs\GF Weather Pipeline Task\lib\site-packages\pydrill\connection\requests_conn.py", line 105, in perform_request
    self._raise_error(response.status_code, raw_data)
  File "C:\Users\Michael\miniconda3\envs\GF Weather Pipeline Task\lib\site-packages\pydrill\connection\base.py", line 113, in _raise_error
    raise HTTP_EXCEPTIONS.get(status_code, TransportError)(status_code, error_message, additional_info)
pydrill.exceptions.TransportError: TransportError(500, '{\r\n  "errorMessage" : "VALIDATION ERROR: From line 8, column 17 to line 8, column 19: Object \'C:/Users/Michael/PycharmProjects/GFWeatherPipelineTask/Data/wether.parquet\' not found within \'dfs\'\\n\\n\\r\\n[Error Id: 84c0f2b3-e07d-4518-99e8-8b9fbadda518 ]"\r\n}')
TransportError(500, '{\r\n  "errorMessage" : "VALIDATION ERROR: From line 2, column 17 to line 2, column 30: Expression \'ObservatinDate\' is not being grouped\\n\\n\\r\\n[Error Id: 08b8b840-3e28-45ef-a289-aaafaff17b4c ]"\r\n}')
Traceback (most recent call last):
  File "C:\Users\Michael\PycharmProjects\GFWeatherPipelineTask\weather_pipeline.py", line 25, in wrapped
    return f(*args, **kwargs)
  File "C:\Users\Michael\PycharmProjects\GFWeatherPipelineTask\weather_pipeline.py", line 354, in query_parquet
    return drill.query(sql, timeout=10)
  File "C:\Users\Michael\miniconda3\envs\GF Weather Pipeline Task\lib\site-packages\pydrill\client\__init__.py", line 62, in query
    'request_timeout': timeout
  File "C:\Users\Michael\miniconda3\envs\GF Weather Pipeline Task\lib\site-packages\pydrill\client\__init__.py", line 24, in perform_request
    return self.transport.perform_request(method, url, params, body)
  File "C:\Users\Michael\miniconda3\envs\GF Weather Pipeline Task\lib\site-packages\pydrill\transport.py", line 79, in perform_request
    timeout=timeout)
  File "C:\Users\Michael\miniconda3\envs\GF Weather Pipeline Task\lib\site-packages\pydrill\connection\requests_conn.py", line 105, in perform_request
    self._raise_error(response.status_code, raw_data)
  File "C:\Users\Michael\miniconda3\envs\GF Weather Pipeline Task\lib\site-packages\pydrill\connection\base.py", line 113, in _raise_error
    raise HTTP_EXCEPTIONS.get(status_code, TransportError)(status_code, error_message, additional_info)
pydrill.exceptions.TransportError: TransportError(500, '{\r\n  "errorMessage" : "VALIDATION ERROR: From line 2, column 17 to line 2, column 30: Expression \'ObservatinDate\' is not being grouped\\n\\n\\r\\n[Error Id: 08b8b840-3e28-45ef-a289-aaafaff17b4c ]"\r\n}')
[Errno 2] File  does not exist: ''
Traceback (most recent call last):
  File "C:\Users\Michael\PycharmProjects\GFWeatherPipelineTask\weather_pipeline.py", line 46, in import_monthly_weather_csv
    frame_out = pd.read_csv(f"{fpath}", na_values=-99).applymap(
  File "C:\Users\Michael\miniconda3\envs\GF Weather Pipeline Task\lib\site-packages\pandas\io\parsers.py", line 676, in parser_f
    return _read(filepath_or_buffer, kwds)
  File "C:\Users\Michael\miniconda3\envs\GF Weather Pipeline Task\lib\site-packages\pandas\io\parsers.py", line 448, in _read
    parser = TextFileReader(fp_or_buf, **kwds)
  File "C:\Users\Michael\miniconda3\envs\GF Weather Pipeline Task\lib\site-packages\pandas\io\parsers.py", line 880, in __init__
    self._make_engine(self.engine)
  File "C:\Users\Michael\miniconda3\envs\GF Weather Pipeline Task\lib\site-packages\pandas\io\parsers.py", line 1114, in _make_engine
    self._engine = CParserWrapper(self.f, **self.options)
  File "C:\Users\Michael\miniconda3\envs\GF Weather Pipeline Task\lib\site-packages\pandas\io\parsers.py", line 1891, in __init__
    self._reader = parsers.TextReader(src, **kwds)
  File "pandas\_libs\parsers.pyx", line 374, in pandas._libs.parsers.TextReader.__cinit__
  File "pandas\_libs\parsers.pyx", line 674, in pandas._libs.parsers.TextReader._setup_parser_source
FileNotFoundError: [Errno 2] File  does not exist: ''
No columns to parse from file
Traceback (most recent call last):
  File "C:\Users\Michael\PycharmProjects\GFWeatherPipelineTask\weather_pipeline.py", line 46, in import_monthly_weather_csv
    frame_out = pd.read_csv(f"{fpath}", na_values=-99).applymap(
  File "C:\Users\Michael\miniconda3\envs\GF Weather Pipeline Task\lib\site-packages\pandas\io\parsers.py", line 676, in parser_f
    return _read(filepath_or_buffer, kwds)
  File "C:\Users\Michael\miniconda3\envs\GF Weather Pipeline Task\lib\site-packages\pandas\io\parsers.py", line 448, in _read
    parser = TextFileReader(fp_or_buf, **kwds)
  File "C:\Users\Michael\miniconda3\envs\GF Weather Pipeline Task\lib\site-packages\pandas\io\parsers.py", line 880, in __init__
    self._make_engine(self.engine)
  File "C:\Users\Michael\miniconda3\envs\GF Weather Pipeline Task\lib\site-packages\pandas\io\parsers.py", line 1114, in _make_engine
    self._engine = CParserWrapper(self.f, **self.options)
  File "C:\Users\Michael\miniconda3\envs\GF Weather Pipeline Task\lib\site-packages\pandas\io\parsers.py", line 1891, in __init__
    self._reader = parsers.TextReader(src, **kwds)
  File "pandas\_libs\parsers.pyx", line 532, in pandas._libs.parsers.TextReader.__cinit__
pandas.errors.EmptyDataError: No columns to parse from file
The file only has a header and no data.
Traceback (most recent call last):
  File "C:\Users\Michael\PycharmProjects\GFWeatherPipelineTask\weather_pipeline.py", line 69, in import_monthly_weather_csv
    raise pd.errors.EmptyDataError("The file only has a header and no data.")
pandas.errors.EmptyDataError: The file only has a header and no data.
'utf-8' codec can't decode byte 0xa3 in position 0: invalid start byte
Traceback (most recent call last):
  File "C:\Users\Michael\PycharmProjects\GFWeatherPipelineTask\weather_pipeline.py", line 46, in import_monthly_weather_csv
    frame_out = pd.read_csv(f"{fpath}", na_values=-99).applymap(
  File "C:\Users\Michael\miniconda3\envs\GF Weather Pipeline Task\lib\site-packages\pandas\io\parsers.py", line 676, in parser_f
    return _read(filepath_or_buffer, kwds)
  File "C:\Users\Michael\miniconda3\envs\GF Weather Pipeline Task\lib\site-packages\pandas\io\parsers.py", line 448, in _read
    parser = TextFileReader(fp_or_buf, **kwds)
  File "C:\Users\Michael\miniconda3\envs\GF Weather Pipeline Task\lib\site-packages\pandas\io\parsers.py", line 880, in __init__
    self._make_engine(self.engine)
  File "C:\Users\Michael\miniconda3\envs\GF Weather Pipeline Task\lib\site-packages\pandas\io\parsers.py", line 1114, in _make_engine
    self._engine = CParserWrapper(self.f, **self.options)
  File "C:\Users\Michael\miniconda3\envs\GF Weather Pipeline Task\lib\site-packages\pandas\io\parsers.py", line 1891, in __init__
    self._reader = parsers.TextReader(src, **kwds)
  File "pandas\_libs\parsers.pyx", line 529, in pandas._libs.parsers.TextReader.__cinit__
  File "pandas\_libs\parsers.pyx", line 749, in pandas._libs.parsers.TextReader._get_header
UnicodeDecodeError: 'utf-8' codec can't decode byte 0xa3 in position 0: invalid start byte
Unexpected column names.
Traceback (most recent call last):
  File "C:\Users\Michael\PycharmProjects\GFWeatherPipelineTask\weather_pipeline.py", line 77, in import_monthly_weather_csv
    raise DataValidationError("Unexpected column names.")
weather_pipeline.DataValidationError: Unexpected column names.
Error tokenizing data. C error: Expected 15 fields in line 3, saw 16
Traceback (most recent call last):
  File "C:\Users\Michael\PycharmProjects\GFWeatherPipelineTask\weather_pipeline.py", line 46, in import_monthly_weather_csv
    frame_out = pd.read_csv(f"{fpath}", na_values=-99).applymap(
  File "C:\Users\Michael\miniconda3\envs\GF Weather Pipeline Task\lib\site-packages\pandas\io\parsers.py", line 676, in parser_f
    return _read(filepath_or_buffer, kwds)
  File "C:\Users\Michael\miniconda3\envs\GF Weather Pipeline Task\lib\site-packages\pandas\io\parsers.py", line 454, in _read
    data = parser.read(nrows)
  File "C:\Users\Michael\miniconda3\envs\GF Weather Pipeline Task\lib\site-packages\pandas\io\parsers.py", line 1133, in read
    ret = self._engine.read(nrows)
  File "C:\Users\Michael\miniconda3\envs\GF Weather Pipeline Task\lib\site-packages\pandas\io\parsers.py", line 2037, in read
    data = self._reader.read(nrows)
  File "pandas\_libs\parsers.pyx", line 860, in pandas._libs.parsers.TextReader.read
  File "pandas\_libs\parsers.pyx", line 875, in pandas._libs.parsers.TextReader._read_low_memory
  File "pandas\_libs\parsers.pyx", line 929, in pandas._libs.parsers.TextReader._read_rows
  File "pandas\_libs\parsers.pyx", line 916, in pandas._libs.parsers.TextReader._tokenize_rows
  File "pandas\_libs\parsers.pyx", line 2071, in pandas._libs.parsers.raise_parser_error
pandas.errors.ParserError: Error tokenizing data. C error: Expected 15 fields in line 3, saw 16

Missing column names or too few row data values.
Traceback (most recent call last):
  File "C:\Users\Michael\PycharmProjects\GFWeatherPipelineTask\weather_pipeline.py", line 72, in import_monthly_weather_csv
    "Missing column names or too few row data values."
weather_pipeline.DataValidationError: Missing column names or too few row data values.
Extra column names or too many row data values.
Traceback (most recent call last):
  File "C:\Users\Michael\PycharmProjects\GFWeatherPipelineTask\weather_pipeline.py", line 75, in import_monthly_weather_csv
    raise DataValidationError("Extra column names or too many row data values.")
weather_pipeline.DataValidationError: Extra column names or too many row data values.
The column ScreenTemperature has a dtype of object which is not a subclass of the required type float64
NoneType: None
The column Longitude has a dtype of object which is not a subclass of the required type float64
NoneType: None
{row: 3, column: "ForecastSiteCode"}: "6" was not in the range [1000, 100000)
NoneType: None
{row: 3, column: "ObservationDate"}: "nan" does not match the date format string "%Y-%m-%dT%H:%M:%S"
NoneType: None
{row: 3, column: "WindDirection"}: "40000" was not in the range [0, 17)
NoneType: None
{row: 3, column: "WindGust"}: "996.0" was not in the range [0, 255)
NoneType: None
{row: 3, column: "ScreenTemperature"}: "KIRKWALL (3017)" was not in the range [-50, 50)
NoneType: None
{row: 3, column: "Pressure"}: "58.95399999999999" was not in the range [870, 1085)
NoneType: None
{row: 3, column: "SignificantWeatherCode"}: "Orkney & Shetland" was not in the range [0, 31)
NoneType: None
{row: 3, column: "Latitude"}: "nan" was not in the range [-90, 90)
NoneType: None
{row: 3, column: "Longitude"}: "nan" was not in the range [-180, 80)
NoneType: None
{row: 6, column: "Longitude"}: "London & South East England" was not in the range [-180, 80)
NoneType: None
{row: 8, column: "ObservationDate"}: "2016-02-07T00:00" does not match the date format string "%Y-%m-%dT%H:%M:%S"
NoneType: None
Data validation failed. Please refer to the log file for detailed information.
Traceback (most recent call last):
  File "C:\Users\Michael\PycharmProjects\GFWeatherPipelineTask\weather_pipeline.py", line 25, in wrapped
    return f(*args, **kwargs)
  File "C:\Users\Michael\PycharmProjects\GFWeatherPipelineTask\weather_pipeline.py", line 204, in validate_weather_data
    "Data validation failed. Please refer to the log file for detailed information."
weather_pipeline.DataValidationError: Data validation failed. Please refer to the log file for detailed information.
TransportError(500, '{\r\n  "errorMessage" : "VALIDATION ERROR: From line 8, column 17 to line 8, column 19: Object \'C:/Users/Michael/PycharmProjects/GFWeatherPipelineTask/Data/wether.parquet\' not found within \'dfs\'\\n\\n\\r\\n[Error Id: 3eb42ebe-399d-48a0-ad7d-febc3942c69b ]"\r\n}')
Traceback (most recent call last):
  File "C:\Users\Michael\PycharmProjects\GFWeatherPipelineTask\weather_pipeline.py", line 25, in wrapped
    return f(*args, **kwargs)
  File "C:\Users\Michael\PycharmProjects\GFWeatherPipelineTask\weather_pipeline.py", line 354, in query_parquet
    return drill.query(sql, timeout=10)
  File "C:\Users\Michael\miniconda3\envs\GF Weather Pipeline Task\lib\site-packages\pydrill\client\__init__.py", line 62, in query
    'request_timeout': timeout
  File "C:\Users\Michael\miniconda3\envs\GF Weather Pipeline Task\lib\site-packages\pydrill\client\__init__.py", line 24, in perform_request
    return self.transport.perform_request(method, url, params, body)
  File "C:\Users\Michael\miniconda3\envs\GF Weather Pipeline Task\lib\site-packages\pydrill\transport.py", line 79, in perform_request
    timeout=timeout)
  File "C:\Users\Michael\miniconda3\envs\GF Weather Pipeline Task\lib\site-packages\pydrill\connection\requests_conn.py", line 105, in perform_request
    self._raise_error(response.status_code, raw_data)
  File "C:\Users\Michael\miniconda3\envs\GF Weather Pipeline Task\lib\site-packages\pydrill\connection\base.py", line 113, in _raise_error
    raise HTTP_EXCEPTIONS.get(status_code, TransportError)(status_code, error_message, additional_info)
pydrill.exceptions.TransportError: TransportError(500, '{\r\n  "errorMessage" : "VALIDATION ERROR: From line 8, column 17 to line 8, column 19: Object \'C:/Users/Michael/PycharmProjects/GFWeatherPipelineTask/Data/wether.parquet\' not found within \'dfs\'\\n\\n\\r\\n[Error Id: 3eb42ebe-399d-48a0-ad7d-febc3942c69b ]"\r\n}')
TransportError(500, '{\r\n  "errorMessage" : "VALIDATION ERROR: From line 8, column 17 to line 8, column 19: Object \'C:/Users/Michael/PycharmProjects/GFWeatherPipelineTask/Data/wether.parquet\' not found within \'dfs\'\\n\\n\\r\\n[Error Id: 3eb42ebe-399d-48a0-ad7d-febc3942c69b ]"\r\n}')
Traceback (most recent call last):
  File "C:\Users\Michael\PycharmProjects\GFWeatherPipelineTask\weather_pipeline.py", line 25, in wrapped
    return f(*args, **kwargs)
  File "C:\Users\Michael\PycharmProjects\GFWeatherPipelineTask\weather_pipeline.py", line 336, in max_daily_average_temperature
    query_out = query_parquet(sql)
  File "C:\Users\Michael\PycharmProjects\GFWeatherPipelineTask\weather_pipeline.py", line 25, in wrapped
    return f(*args, **kwargs)
  File "C:\Users\Michael\PycharmProjects\GFWeatherPipelineTask\weather_pipeline.py", line 354, in query_parquet
    return drill.query(sql, timeout=10)
  File "C:\Users\Michael\miniconda3\envs\GF Weather Pipeline Task\lib\site-packages\pydrill\client\__init__.py", line 62, in query
    'request_timeout': timeout
  File "C:\Users\Michael\miniconda3\envs\GF Weather Pipeline Task\lib\site-packages\pydrill\client\__init__.py", line 24, in perform_request
    return self.transport.perform_request(method, url, params, body)
  File "C:\Users\Michael\miniconda3\envs\GF Weather Pipeline Task\lib\site-packages\pydrill\transport.py", line 79, in perform_request
    timeout=timeout)
  File "C:\Users\Michael\miniconda3\envs\GF Weather Pipeline Task\lib\site-packages\pydrill\connection\requests_conn.py", line 105, in perform_request
    self._raise_error(response.status_code, raw_data)
  File "C:\Users\Michael\miniconda3\envs\GF Weather Pipeline Task\lib\site-packages\pydrill\connection\base.py", line 113, in _raise_error
    raise HTTP_EXCEPTIONS.get(status_code, TransportError)(status_code, error_message, additional_info)
pydrill.exceptions.TransportError: TransportError(500, '{\r\n  "errorMessage" : "VALIDATION ERROR: From line 8, column 17 to line 8, column 19: Object \'C:/Users/Michael/PycharmProjects/GFWeatherPipelineTask/Data/wether.parquet\' not found within \'dfs\'\\n\\n\\r\\n[Error Id: 3eb42ebe-399d-48a0-ad7d-febc3942c69b ]"\r\n}')
TransportError(500, '{\r\n  "errorMessage" : "VALIDATION ERROR: From line 2, column 17 to line 2, column 30: Expression \'ObservatinDate\' is not being grouped\\n\\n\\r\\n[Error Id: 6d485554-fbde-4d5c-b4d8-2beedbbcf655 ]"\r\n}')
Traceback (most recent call last):
  File "C:\Users\Michael\PycharmProjects\GFWeatherPipelineTask\weather_pipeline.py", line 25, in wrapped
    return f(*args, **kwargs)
  File "C:\Users\Michael\PycharmProjects\GFWeatherPipelineTask\weather_pipeline.py", line 354, in query_parquet
    return drill.query(sql, timeout=10)
  File "C:\Users\Michael\miniconda3\envs\GF Weather Pipeline Task\lib\site-packages\pydrill\client\__init__.py", line 62, in query
    'request_timeout': timeout
  File "C:\Users\Michael\miniconda3\envs\GF Weather Pipeline Task\lib\site-packages\pydrill\client\__init__.py", line 24, in perform_request
    return self.transport.perform_request(method, url, params, body)
  File "C:\Users\Michael\miniconda3\envs\GF Weather Pipeline Task\lib\site-packages\pydrill\transport.py", line 79, in perform_request
    timeout=timeout)
  File "C:\Users\Michael\miniconda3\envs\GF Weather Pipeline Task\lib\site-packages\pydrill\connection\requests_conn.py", line 105, in perform_request
    self._raise_error(response.status_code, raw_data)
  File "C:\Users\Michael\miniconda3\envs\GF Weather Pipeline Task\lib\site-packages\pydrill\connection\base.py", line 113, in _raise_error
    raise HTTP_EXCEPTIONS.get(status_code, TransportError)(status_code, error_message, additional_info)
pydrill.exceptions.TransportError: TransportError(500, '{\r\n  "errorMessage" : "VALIDATION ERROR: From line 2, column 17 to line 2, column 30: Expression \'ObservatinDate\' is not being grouped\\n\\n\\r\\n[Error Id: 6d485554-fbde-4d5c-b4d8-2beedbbcf655 ]"\r\n}')
